Workbook
Name Cameras: OFFSET(Analysis!$I$42, 0, 0, MAX(1, COUNTA(Analysis!$I$42:$I$57)), 1)
Name COUNTS: OFFSET(Analysis!$D$3, 0, 0, MAX(1, COUNTA(Analysis!$D$3:$D$26)), 1)
Name DailyAvg: OFFSET(Analysis!$H$42, 0, 0, MAX(1, COUNTA(Analysis!$H$42:$H$57)), 1)
Name days: OFFSET(Analysis!$G$42, 0, 0, MAX(1, COUNTA(Analysis!$G$42:$G$57)), 1)
Name Less_sever: OFFSET(Analysis!$D$42, 0, 0, MAX(1, COUNTA(Analysis!$D$42:$D$57)), 1)
Name Locations: OFFSET(Analysis!$C$42, 0, 0, MAX(1, COUNTA(Analysis!$C$42:$C$57)), 1)
Name More_severe: OFFSET(Analysis!$E$42, 0, 0, MAX(1, COUNTA(Analysis!$E$42:$E$57)), 1)
Name Per_camera_avg: OFFSET(Analysis!$J$42, 0, 0, MAX(1, COUNTA(Analysis!$J$42:$J$57)), 1)
Name Rejected: OFFSET(Analysis!$M$42, 0, 0, MAX(1, COUNTA(Analysis!$M$42:$M$57)), 1)
Name Resolved: OFFSET(Analysis!$L$42, 0, 0, MAX(1, COUNTA(Analysis!$L$42:$L$57)), 1)
Name Slicer_locations: #N/A
Name Slicer_STATE: #N/A
Name Slicer_Violation_Type: #N/A
Name Total_violations: OFFSET(Analysis!$F$42, 0, 0, MAX(1, COUNTA(Analysis!$F$42:$F$57)), 1)
Name Unresolved: OFFSET(Analysis!$K$42, 0, 0, MAX(1, COUNTA(Analysis!$K$42:$K$57)), 1)
Name VIOLATIONS: OFFSET(Analysis!$C$3, 0, 0, MAX(1, COUNTA(Analysis!$C$3:$C$26)), 1)

Sheet Raw Data
A1: violation_timestamp | B1: violation_name | C1: Location | D1: Camera Name | E1: image_url | F1: Action Status | G1: Action Status-1 | H1: image | I1: resolve | J1: week_num | K1: Date | L1: Time(UTC) | M1: Shift | N1: Buttons | O1: images
A2: 01-May-2025 09:52:26 | B2: PPE | C2: Lucknow | D2: Fuel Farm -NRP (Front) | E2: https://smile-ai-test.s3.ap-south-1.amazonaws.com/content/violation/ppe/frame/41370_20250501T042225_ppe_p.jpg | F2: 0 | G2: =IF(ISBLANK(A2), "", IF(ISBLANK(F2), 0, F2)) -> 0 | H2: =IF(ISBLANK(E2),"",HYPERLINK(E2,"Click here")) -> Click here | I2: =IFERROR(INDEX(Analysis!$B$71:$L$91, MATCH(B2, Analysis!$A$71:$A$91, 0), MATCH(C2, Analysis!$B$70:$L$70, 0)), "") -> Mild | J2: =IF(ISBLANK(A2),"",WEEKNUM(A2)) -> 18 | K2: =IF(ISBLANK(A2),"",DATE(YEAR(A2),MONTH(A2),DAY(A2))) -> 45778 | L2: =IF(A2="", "", A2 - INT(A2)) -> 0.41141204 | M2: {=IF(L2="","",_xlfn.IFS( AND(L2>=TIME(9,0,0), L2<TIME(16,0,0)),"Morning", AND(L2>=TIME(16,0,0), L2<TIME(23,59,0)),"Evening", L2>=TIME(23,59,0),"Night", L2<TIME(9,0,0),"Night" ))} -> Morning | N2: On | O2: =IF(N2="ON", _xlfn.IMAGE(E2, 1), "") -> #VALUE!
A3: 01-May-2025 10:04:27 | B3: Vehicle Reverse Flagman | C3: Ahmedabad | D3: JCPL Plant | E3: https://smile-ai-test.s3.ap-south-1.amazonaws.com/content/violation/flagman/frame/20949_20250501T043426_flagman_p.jpg | F3: 0 | G3: =IF(ISBLANK(A3), "", IF(ISBLANK(F3), 0, F3)) -> 0 | H3: =IF(ISBLANK(E3),"",HYPERLINK(E3,"Click here")) -> Click here | I3: =IFERROR(INDEX(Analysis!$B$71:$L$91, MATCH(B3, Analysis!$A$71:$A$91, 0), MATCH(C3, Analysis!$B$70:$L$70, 0)), "") -> Severe | J3: =IF(ISBLANK(A3),"",WEEKNUM(A3)) -> 18 | K3: =IF(ISBLANK(A3),"",DATE(YEAR(A3),MONTH(A3),DAY(A3))) -> 45778 | L3: =IF(A3="", "", A3 - INT(A3)) -> 0.41975694 | M3: {=IF(L3="","",_xlfn.IFS( AND(L3>=TIME(9,0,0), L3<TIME(16,0,0)),"Morning", AND(L3>=TIME(16,0,0), L3<TIME(23,59,0)),"Evening", L3>=TIME(23,59,0),"Night", L3<TIME(9,0,0),"Night" ))} -> Morning | O3: =IF(N3="ON", _xlfn.IMAGE(E3, 1), "")
A4: 01-May-2025 10:13:42 | B4: Welding / Gas cutting | C4: Guwahati | D4: City Side Overbridge 1 | E4: https://smile-ai-test.s3.ap-south-1.amazonaws.com/content/violation/fire/frame/13380_20250501T044340_fire_p.jpg | F4: 0 | G4: =IF(ISBLANK(A4), "", IF(ISBLANK(F4), 0, F4)) -> 0 | H4: =IF(ISBLANK(E4),"",HYPERLINK(E4,"Click here")) -> Click here | I4: =IFERROR(INDEX(Analysis!$B$71:$L$91, MATCH(B4, Analysis!$A$71:$A$91, 0), MATCH(C4, Analysis!$B$70:$L$70, 0)), "") -> Mild | J4: =IF(ISBLANK(A4),"",WEEKNUM(A4)) -> 18 | K4: =IF(ISBLANK(A4),"",DATE(YEAR(A4),MONTH(A4),DAY(A4))) -> 45778 | L4: =IF(A4="", "", A4 - INT(A4)) -> 0.42618056 | M4: {=IF(L4="","",_xlfn.IFS( AND(L4>=TIME(9,0,0), L4<TIME(16,0,0)),"Morning", AND(L4>=TIME(16,0,0), L4<TIME(23,59,0)),"Evening", L4>=TIME(23,59,0),"Night", L4<TIME(9,0,0),"Night" ))} -> Morning | O4: =IF(N4="ON", _xlfn.IMAGE(E4, 1), "")
A5: 01-May-2025 10:29:53 | B5: PPE | C5: Guwahati | D5: Arrival Zone 4 | E5: https://smile-ai-test.s3.ap-south-1.amazonaws.com/content/violation/ppe/frame/62373_20250501T045951_ppe_p.jpg | F5: 0 | G5: =IF(ISBLANK(A5), "", IF(ISBLANK(F5), 0, F5)) -> 0 | H5: =IF(ISBLANK(E5),"",HYPERLINK(E5,"Click here")) -> Click here | I5: =IFERROR(INDEX(Analysis!$B$71:$L$91, MATCH(B5, Analysis!$A$71:$A$91, 0), MATCH(C5, Analysis!$B$70:$L$70, 0)), "") -> Mild | J5: =IF(ISBLANK(A5),"",WEEKNUM(A5)) -> 18 | K5: =IF(ISBLANK(A5),"",DATE(YEAR(A5),MONTH(A5),DAY(A5))) -> 45778 | L5: =IF(A5="", "", A5 - INT(A5)) -> 0.43741898 | M5: {=IF(L5="","",_xlfn.IFS( AND(L5>=TIME(9,0,0), L5<TIME(16,0,0)),"Morning", AND(L5>=TIME(16,0,0), L5<TIME(23,59,0)),"Evening", L5>=TIME(23,59,0),"Night", L5<TIME(9,0,0),"Night" ))} -> Morning | O5: =IF(N5="ON", _xlfn.IMAGE(E5, 1), "")
A6: 01-May-2025 10:34:43 | B6: PPE | C6: Jaipur | D6: JKG - T1 Parking Camera 2 | E6: https://smile-ai-test.s3.ap-south-1.amazonaws.com/content/violation/ppe/frame/20186_20250501T050441_ppe_p.jpg | F6: 0 | G6: =IF(ISBLANK(A6), "", IF(ISBLANK(F6), 0, F6)) -> 0 | H6: =IF(ISBLANK(E6),"",HYPERLINK(E6,"Click here")) -> Click here | I6: =IFERROR(INDEX(Analysis!$B$71:$L$91, MATCH(B6, Analysis!$A$71:$A$91, 0), MATCH(C6, Analysis!$B$70:$L$70, 0)), "") -> Mild | J6: =IF(ISBLANK(A6),"",WEEKNUM(A6)) -> 18 | K6: =IF(ISBLANK(A6),"",DATE(YEAR(A6),MONTH(A6),DAY(A6))) -> 45778 | L6: =IF(A6="", "", A6 - INT(A6)) -> 0.44077546 | M6: {=IF(L6="","",_xlfn.IFS( AND(L6>=TIME(9,0,0), L6<TIME(16,0,0)),"Morning", AND(L6>=TIME(16,0,0), L6<TIME(23,59,0)),"Evening", L6>=TIME(23,59,0),"Night", L6<TIME(9,0,0),"Night" ))} -> Morning | O6: =IF(N6="ON", _xlfn.IMAGE(E6, 1), "")
A7: 01-May-2025 10:35:07 | B7: PPE | C7: Jaipur | D7: JKG T-01 Camera 1 | E7: https://smile-ai-test.s3.ap-south-1.amazonaws.com/content/violation/ppe/frame/99896_20250501T050505_ppe_p.jpg | F7: 0 | G7: =IF(ISBLANK(A7), "", IF(ISBLANK(F7), 0, F7)) -> 0 | H7: =IF(ISBLANK(E7),"",HYPERLINK(E7,"Click here")) -> Click here | I7: =IFERROR(INDEX(Analysis!$B$71:$L$91, MATCH(B7, Analysis!$A$71:$A$91, 0), MATCH(C7, Analysis!$B$70:$L$70, 0)), "") -> Mild | J7: =IF(ISBLANK(A7),"",WEEKNUM(A7)) -> 18 | K7: =IF(ISBLANK(A7),"",DATE(YEAR(A7),MONTH(A7),DAY(A7))) -> 45778 | L7: =IF(A7="", "", A7 - INT(A7)) -> 0.44105324 | M7: {=IF(L7="","",_xlfn.IFS( AND(L7>=TIME(9,0,0), L7<TIME(16,0,0)),"Morning", AND(L7>=TIME(16,0,0), L7<TIME(23,59,0)),"Evening", L7>=TIME(23,59,0),"Night", L7<TIME(9,0,0),"Night" ))} -> Morning | O7: =IF(N7="ON", _xlfn.IMAGE(E7, 1), "")
A8: 01-May-2025 10:50:03 | B8: PPE | C8: Jaipur | D8: Bambala 2 | E8: https://smile-ai-test.s3.ap-south-1.amazonaws.com/content/violation/ppe/frame/38969_20250501T052000_ppe_p.jpg | F8: 0 | G8: =IF(ISBLANK(A8), "", IF(ISBLANK(F8), 0, F8)) -> 0 | H8: =IF(ISBLANK(E8),"",HYPERLINK(E8,"Click here")) -> Click here | I8: =IFERROR(INDEX(Analysis!$B$71:$L$91, MATCH(B8, Analysis!$A$71:$A$91, 0), MATCH(C8, Analysis!$B$70:$L$70, 0)), "") -> Mild | J8: =IF(ISBLANK(A8),"",WEEKNUM(A8)) -> 18 | K8: =IF(ISBLANK(A8),"",DATE(YEAR(A8),MONTH(A8),DAY(A8))) -> 45778 | L8: =IF(A8="", "", A8 - INT(A8)) -> 0.45142361 | M8: {=IF(L8="","",_xlfn.IFS( AND(L8>=TIME(9,0,0), L8<TIME(16,0,0)),"Morning", AND(L8>=TIME(16,0,0), L8<TIME(23,59,0)),"Evening", L8>=TIME(23,59,0),"Night", L8<TIME(9,0,0),"Night" ))} -> Morning | O8: =IF(N8="ON", _xlfn.IMAGE(E8, 1), "")
A9: 01-May-2025 11:01:25 | B9: PPE | C9: Guwahati | D9: Arrival Zone 4 | E9: https://smile-ai-test.s3.ap-south-1.amazonaws.com/content/violation/ppe/frame/41180_20250501T053123_ppe_p.jpg | F9: 0 | G9: =IF(ISBLANK(A9), "", IF(ISBLANK(F9), 0, F9)) -> 0 | H9: =IF(ISBLANK(E9),"",HYPERLINK(E9,"Click here")) -> Click here | I9: =IFERROR(INDEX(Analysis!$B$71:$L$91, MATCH(B9, Analysis!$A$71:$A$91, 0), MATCH(C9, Analysis!$B$70:$L$70, 0)), "") -> Mild | J9: =IF(ISBLANK(A9),"",WEEKNUM(A9)) -> 18 | K9: =IF(ISBLANK(A9),"",DATE(YEAR(A9),MONTH(A9),DAY(A9))) -> 45778 | L9: =IF(A9="", "", A9 - INT(A9)) -> 0.45931713 | M9: {=IF(L9="","",_xlfn.IFS( AND(L9>=TIME(9,0,0), L9<TIME(16,0,0)),"Morning", AND(L9>=TIME(16,0,0), L9<TIME(23,59,0)),"Evening", L9>=TIME(23,59,0),"Night", L9<TIME(9,0,0),"Night" ))} -> Morning | O9: =IF(N9="ON", _xlfn.IMAGE(E9, 1), "")
A10: 01-May-2025 11:33:15 | B10: Phone At Work | C10: Lucknow | D10: Zone 5 NCC Slab | E10: https://smile-ai-test.s3.ap-south-1.amazonaws.com/content/violation/phone/frame/32882_20250501T060313_phone_p.jpg | F10: 0 | G10: =IF(ISBLANK(A10), "", IF(ISBLANK(F10), 0, F10)) -> 0 | H10: =IF(ISBLANK(E10),"",HYPERLINK(E10,"Click here")) -> Click here | I10: =IFERROR(INDEX(Analysis!$B$71:$L$91, MATCH(B10, Analysis!$A$71:$A$91, 0), MATCH(C10, Analysis!$B$70:$L$70, 0)), "") -> Mild | J10: =IF(ISBLANK(A10),"",WEEKNUM(A10)) -> 18 | K10: =IF(ISBLANK(A10),"",DATE(YEAR(A10),MONTH(A10),DAY(A10))) -> 45778 | L10: =IF(A10="", "", A10 - INT(A10)) -> 0.48142361 | M10: {=IF(L10="","",_xlfn.IFS( AND(L10>=TIME(9,0,0), L10<TIME(16,0,0)),"Morning", AND(L10>=TIME(16,0,0), L10<TIME(23,59,0)),"Evening", L10>=TIME(23,59,0),"Night", L10<TIME(9,0,0),"Night" ))} -> Morning | O10: =IF(N10="ON", _xlfn.IMAGE(E10, 1), "")
A11: 01-May-2025 11:49:23 | B11: PPE | C11: Thiruvananthapuram | D11: Terminal 2 (C) | E11: https://smile-ai-test.s3.ap-south-1.amazonaws.com/content/violation/ppe/frame/26162_20250501T061921_ppe_p.jpg | F11: 2 | G11: =IF(ISBLANK(A11), "", IF(ISBLANK(F11), 0, F11)) -> 2 | H11: =IF(ISBLANK(E11),"",HYPERLINK(E11,"Click here")) -> Click here | I11: =IFERROR(INDEX(Analysis!$B$71:$L$91, MATCH(B11, Analysis!$A$71:$A$91, 0), MATCH(C11, Analysis!$B$70:$L$70, 0)), "") -> Mild | J11: =IF(ISBLANK(A11),"",WEEKNUM(A11)) -> 18 | K11: =IF(ISBLANK(A11),"",DATE(YEAR(A11),MONTH(A11),DAY(A11))) -> 45778 | L11: =IF(A11="", "", A11 - INT(A11)) -> 0.49262731 | M11: {=IF(L11="","",_xlfn.IFS( AND(L11>=TIME(9,0,0), L11<TIME(16,0,0)),"Morning", AND(L11>=TIME(16,0,0), L11<TIME(23,59,0)),"Evening", L11>=TIME(23,59,0),"Night", L11<TIME(9,0,0),"Night" ))} -> Morning | O11: =IF(N11="ON", _xlfn.IMAGE(E11, 1), "")
A12: 01-May-2025 12:22:43 | B12: Vehicle Reverse Flagman | C12: Ahmedabad | D12: JCPL Plant | E12: https://smile-ai-test.s3.ap-south-1.amazonaws.com/content/violation/flagman/frame/99453_20250501T065242_flagman_p.jpg | F12: 2 | G12: =IF(ISBLANK(A12), "", IF(ISBLANK(F12), 0, F12)) -> 2 | H12: =IF(ISBLANK(E12),"",HYPERLINK(E12,"Click here")) -> Click here | I12: =IFERROR(INDEX(Analysis!$B$71:$L$91, MATCH(B12, Analysis!$A$71:$A$91, 0), MATCH(C12, Analysis!$B$70:$L$70, 0)), "") -> Severe | J12: =IF(ISBLANK(A12),"",WEEKNUM(A12)) -> 18 | K12: =IF(ISBLANK(A12),"",DATE(YEAR(A12),MONTH(A12),DAY(A12))) -> 45778 | L12: =IF(A12="", "", A12 - INT(A12)) -> 0.51577546 | M12: {=IF(L12="","",_xlfn.IFS( AND(L12>=TIME(9,0,0), L12<TIME(16,0,0)),"Morning", AND(L12>=TIME(16,0,0), L12<TIME(23,59,0)),"Evening", L12>=TIME(23,59,0),"Night", L12<TIME(9,0,0),"Night" ))} -> Morning | O12: =IF(N12="ON", _xlfn.IMAGE(E12, 1), "")
A13: 01-May-2025 12:39:35 | B13: PPE | C13: Mangalore | D13: Precision approach X | E13: https://smile-ai-test.s3.ap-south-1.amazonaws.com/content/violation/ppe/frame/99702_20250501T070934_ppe_p.jpg | F13: 2 | G13: =IF(ISBLANK(A13), "", IF(ISBLANK(F13), 0, F13)) -> 2 | H13: =IF(ISBLANK(E13),"",HYPERLINK(E13,"Click here")) -> Click here | I13: =IFERROR(INDEX(Analysis!$B$71:$L$91, MATCH(B13, Analysis!$A$71:$A$91, 0), MATCH(C13, Analysis!$B$70:$L$70, 0)), "") -> Mild | J13: =IF(ISBLANK(A13),"",WEEKNUM(A13)) -> 18 | K13: =IF(ISBLANK(A13),"",DATE(YEAR(A13),MONTH(A13),DAY(A13))) -> 45778 | L13: =IF(A13="", "", A13 - INT(A13)) -> 0.52748843 | M13: {=IF(L13="","",_xlfn.IFS( AND(L13>=TIME(9,0,0), L13<TIME(16,0,0)),"Morning", AND(L13>=TIME(16,0,0), L13<TIME(23,59,0)),"Evening", L13>=TIME(23,59,0),"Night", L13<TIME(9,0,0),"Night" ))} -> Morning | O13: =IF(N13="ON", _xlfn.IMAGE(E13, 1), "")
A14: 01-May-2025 12:39:49 | B14: PPE | C14: Mangalore | D14: Precision approach X | E14: https://smile-ai-test.s3.ap-south-1.amazonaws.com/content/violation/ppe/frame/13499_20250501T070948_ppe_p.jpg | F14: 2 | G14: =IF(ISBLANK(A14), "", IF(ISBLANK(F14), 0, F14)) -> 2 | H14: =IF(ISBLANK(E14),"",HYPERLINK(E14,"Click here")) -> Click here | I14: =IFERROR(INDEX(Analysis!$B$71:$L$91, MATCH(B14, Analysis!$A$71:$A$91, 0), MATCH(C14, Analysis!$B$70:$L$70, 0)), "") -> Mild | J14: =IF(ISBLANK(A14),"",WEEKNUM(A14)) -> 18 | K14: =IF(ISBLANK(A14),"",DATE(YEAR(A14),MONTH(A14),DAY(A14))) -> 45778 | L14: =IF(A14="", "", A14 - INT(A14)) -> 0.52765046 | M14: {=IF(L14="","",_xlfn.IFS( AND(L14>=TIME(9,0,0), L14<TIME(16,0,0)),"Morning", AND(L14>=TIME(16,0,0), L14<TIME(23,59,0)),"Evening", L14>=TIME(23,59,0),"Night", L14<TIME(9,0,0),"Night" ))} -> Morning | O14: =IF(N14="ON", _xlfn.IMAGE(E14, 1), "")
A15: 01-May-2025 12:40:53 | B15: PPE | C15: Mangalore | D15: Precision approach X | E15: https://smile-ai-test.s3.ap-south-1.amazonaws.com/content/violation/ppe/frame/13768_20250501T071052_ppe_p.jpg | F15: 2 | G15: =IF(ISBLANK(A15), "", IF(ISBLANK(F15), 0, F15)) -> 2 | H15: =IF(ISBLANK(E15),"",HYPERLINK(E15,"Click here")) -> Click here | I15: =IFERROR(INDEX(Analysis!$B$71:$L$91, MATCH(B15, Analysis!$A$71:$A$91, 0), MATCH(C15, Analysis!$B$70:$L$70, 0)), "") -> Mild | J15: =IF(ISBLANK(A15),"",WEEKNUM(A15)) -> 18 | K15: =IF(ISBLANK(A15),"",DATE(YEAR(A15),MONTH(A15),DAY(A15))) -> 45778 | L15: =IF(A15="", "", A15 - INT(A15)) -> 0.5283912 | M15: {=IF(L15="","",_xlfn.IFS( AND(L15>=TIME(9,0,0), L15<TIME(16,0,0)),"Morning", AND(L15>=TIME(16,0,0), L15<TIME(23,59,0)),"Evening", L15>=TIME(23,59,0),"Night", L15<TIME(9,0,0),"Night" ))} -> Morning | O15: =IF(N15="ON", _xlfn.IMAGE(E15, 1), "")
A16: 01-May-2025 12:53:04 | B16: Vehicle Reverse Flagman | C16: Lucknow | D16: Zone 5 NCC | E16: https://smile-ai-test.s3.ap-south-1.amazonaws.com/content/violation/flagman/frame/84476_20250501T072302_flagman_p.jpg | F16: 2 | G16: =IF(ISBLANK(A16), "", IF(ISBLANK(F16), 0, F16)) -> 2 | H16: =IF(ISBLANK(E16),"",HYPERLINK(E16,"Click here")) -> Click here | I16: =IFERROR(INDEX(Analysis!$B$71:$L$91, MATCH(B16, Analysis!$A$71:$A$91, 0), MATCH(C16, Analysis!$B$70:$L$70, 0)), "") -> Severe | J16: =IF(ISBLANK(A16),"",WEEKNUM(A16)) -> 18 | K16: =IF(ISBLANK(A16),"",DATE(YEAR(A16),MONTH(A16),DAY(A16))) -> 45778 | L16: =IF(A16="", "", A16 - INT(A16)) -> 0.53685185 | M16: {=IF(L16="","",_xlfn.IFS( AND(L16>=TIME(9,0,0), L16<TIME(16,0,0)),"Morning", AND(L16>=TIME(16,0,0), L16<TIME(23,59,0)),"Evening", L16>=TIME(23,59,0),"Night", L16<TIME(9,0,0),"Night" ))} -> Morning | O16: =IF(N16="ON", _xlfn.IMAGE(E16, 1), "")
A17: 01-May-2025 14:11:39 | B17: Vehicle Reverse Flagman | C17: Ahmedabad | D17: CSD - East Side | E17: https://smile-ai-test.s3.ap-south-1.amazonaws.com/content/violation/flagman/frame/66187_20250501T084138_flagman_p.jpg | F17: 2 | G17: =IF(ISBLANK(A17), "", IF(ISBLANK(F17), 0, F17)) -> 2 | H17: =IF(ISBLANK(E17),"",HYPERLINK(E17,"Click here")) -> Click here | I17: =IFERROR(INDEX(Analysis!$B$71:$L$91, MATCH(B17, Analysis!$A$71:$A$91, 0), MATCH(C17, Analysis!$B$70:$L$70, 0)), "") -> Severe | J17: =IF(ISBLANK(A17),"",WEEKNUM(A17)) -> 18 | K17: =IF(ISBLANK(A17),"",DATE(YEAR(A17),MONTH(A17),DAY(A17))) -> 45778 | L17: =IF(A17="", "", A17 - INT(A17)) -> 0.59142361 | M17: {=IF(L17="","",_xlfn.IFS( AND(L17>=TIME(9,0,0), L17<TIME(16,0,0)),"Morning", AND(L17>=TIME(16,0,0), L17<TIME(23,59,0)),"Evening", L17>=TIME(23,59,0),"Night", L17<TIME(9,0,0),"Night" ))} -> Morning | O17: =IF(N17="ON", _xlfn.IMAGE(E17, 1), "")
A18: 01-May-2025 14:21:16 | B18: Vehicle Reverse Flagman | C18: Ahmedabad | D18: JCPL Plant | E18: https://smile-ai-test.s3.ap-south-1.amazonaws.com/content/violation/flagman/frame/62660_20250501T085114_flagman_p.jpg | F18: 2 | G18: =IF(ISBLANK(A18), "", IF(ISBLANK(F18), 0, F18)) -> 2 | H18: =IF(ISBLANK(E18),"",HYPERLINK(E18,"Click here")) -> Click here | I18: =IFERROR(INDEX(Analysis!$B$71:$L$91, MATCH(B18, Analysis!$A$71:$A$91, 0), MATCH(C18, Analysis!$B$70:$L$70, 0)), "") -> Severe | J18: =IF(ISBLANK(A18),"",WEEKNUM(A18)) -> 18 | K18: =IF(ISBLANK(A18),"",DATE(YEAR(A18),MONTH(A18),DAY(A18))) -> 45778 | L18: =IF(A18="", "", A18 - INT(A18)) -> 0.59810185 | M18: {=IF(L18="","",_xlfn.IFS( AND(L18>=TIME(9,0,0), L18<TIME(16,0,0)),"Morning", AND(L18>=TIME(16,0,0), L18<TIME(23,59,0)),"Evening", L18>=TIME(23,59,0),"Night", L18<TIME(9,0,0),"Night" ))} -> Morning | O18: =IF(N18="ON", _xlfn.IMAGE(E18, 1), "")
A19: 01-May-2025 14:43:32 | B19: Work At Height | C19: Jaipur | D19: Bambala 2 | E19: https://smile-ai-test.s3.ap-south-1.amazonaws.com/content/violation/wah/frame/81595_20250501T091330_wah_p.jpg | F19: 2 | G19: =IF(ISBLANK(A19), "", IF(ISBLANK(F19), 0, F19)) -> 2 | H19: =IF(ISBLANK(E19),"",HYPERLINK(E19,"Click here")) -> Click here | I19: =IFERROR(INDEX(Analysis!$B$71:$L$91, MATCH(B19, Analysis!$A$71:$A$91, 0), MATCH(C19, Analysis!$B$70:$L$70, 0)), "") -> Severe | J19: =IF(ISBLANK(A19),"",WEEKNUM(A19)) -> 18 | K19: =IF(ISBLANK(A19),"",DATE(YEAR(A19),MONTH(A19),DAY(A19))) -> 45778 | L19: =IF(A19="", "", A19 - INT(A19)) -> 0.61356481 | M19: {=IF(L19="","",_xlfn.IFS( AND(L19>=TIME(9,0,0), L19<TIME(16,0,0)),"Morning", AND(L19>=TIME(16,0,0), L19<TIME(23,59,0)),"Evening", L19>=TIME(23,59,0),"Night", L19<TIME(9,0,0),"Night" ))} -> Morning | O19: =IF(N19="ON", _xlfn.IMAGE(E19, 1), "")
A20: 01-May-2025 14:53:49 | B20: PPE | C20: Ahmedabad | D20: JCPL Plant | E20: https://smile-ai-test.s3.ap-south-1.amazonaws.com/content/violation/ppe/frame/10525_20250501T092348_ppe_p.jpg | F20: 2 | G20: =IF(ISBLANK(A20), "", IF(ISBLANK(F20), 0, F20)) -> 2 | H20: =IF(ISBLANK(E20),"",HYPERLINK(E20,"Click here")) -> Click here | I20: =IFERROR(INDEX(Analysis!$B$71:$L$91, MATCH(B20, Analysis!$A$71:$A$91, 0), MATCH(C20, Analysis!$B$70:$L$70, 0)), "") -> Mild | J20: =IF(ISBLANK(A20),"",WEEKNUM(A20)) -> 18 | K20: =IF(ISBLANK(A20),"",DATE(YEAR(A20),MONTH(A20),DAY(A20))) -> 45778 | L20: =IF(A20="", "", A20 - INT(A20)) -> 0.62070602 | M20: {=IF(L20="","",_xlfn.IFS( AND(L20>=TIME(9,0,0), L20<TIME(16,0,0)),"Morning", AND(L20>=TIME(16,0,0), L20<TIME(23,59,0)),"Evening", L20>=TIME(23,59,0),"Night", L20<TIME(9,0,0),"Night" ))} -> Morning | O20: =IF(N20="ON", _xlfn.IMAGE(E20, 1), "")
A21: 01-May-2025 15:07:18 | B21: PPE | C21: Ahmedabad | D21: JCPL Plant | E21: https://smile-ai-test.s3.ap-south-1.amazonaws.com/content/violation/ppe/frame/17917_20250501T093716_ppe_p.jpg | F21: 2 | G21: =IF(ISBLANK(A21), "", IF(ISBLANK(F21), 0, F21)) -> 2 | H21: =IF(ISBLANK(E21),"",HYPERLINK(E21,"Click here")) -> Click here | I21: =IFERROR(INDEX(Analysis!$B$71:$L$91, MATCH(B21, Analysis!$A$71:$A$91, 0), MATCH(C21, Analysis!$B$70:$L$70, 0)), "") -> Mild | J21: =IF(ISBLANK(A21),"",WEEKNUM(A21)) -> 18 | K21: =IF(ISBLANK(A21),"",DATE(YEAR(A21),MONTH(A21),DAY(A21))) -> 45778 | L21: =IF(A21="", "", A21 - INT(A21)) -> 0.63006944 | M21: {=IF(L21="","",_xlfn.IFS( AND(L21>=TIME(9,0,0), L21<TIME(16,0,0)),"Morning", AND(L21>=TIME(16,0,0), L21<TIME(23,59,0)),"Evening", L21>=TIME(23,59,0),"Night", L21<TIME(9,0,0),"Night" ))} -> Morning | O21: =IF(N21="ON", _xlfn.IMAGE(E21, 1), "")
A22: 01-May-2025 15:07:37 | B22: PPE | C22: Ahmedabad | D22: JCPL Plant | E22: https://smile-ai-test.s3.ap-south-1.amazonaws.com/content/violation/ppe/frame/90916_20250501T093736_ppe_p.jpg | F22: 2 | G22: =IF(ISBLANK(A22), "", IF(ISBLANK(F22), 0, F22)) -> 2 | H22: =IF(ISBLANK(E22),"",HYPERLINK(E22,"Click here")) -> Click here | I22: =IFERROR(INDEX(Analysis!$B$71:$L$91, MATCH(B22, Analysis!$A$71:$A$91, 0), MATCH(C22, Analysis!$B$70:$L$70, 0)), "") -> Mild | J22: =IF(ISBLANK(A22),"",WEEKNUM(A22)) -> 18 | K22: =IF(ISBLANK(A22),"",DATE(YEAR(A22),MONTH(A22),DAY(A22))) -> 45778 | L22: =IF(A22="", "", A22 - INT(A22)) -> 0.63028935 | M22: {=IF(L22="","",_xlfn.IFS( AND(L22>=TIME(9,0,0), L22<TIME(16,0,0)),"Morning", AND(L22>=TIME(16,0,0), L22<TIME(23,59,0)),"Evening", L22>=TIME(23,59,0),"Night", L22<TIME(9,0,0),"Night" ))} -> Morning | O22: =IF(N22="ON", _xlfn.IMAGE(E22, 1), "")
... A51: 02-May-2025 10:08:44 | B51: PPE | C51: Guwahati | D51: AirSide | E51: https://smile-ai-test.s3.ap-south-1.amazonaws.com/content/violation/ppe/frame/26808_20250502T043843_ppe_p.jpg | F51: 2 | G51: =IF(ISBLANK(A51), "", IF(ISBLANK(F51), 0, F51)) -> 2 | H51: =IF(ISBLANK(E51),"",HYPERLINK(E51,"Click here")) -> Click here | I51: =IFERROR(INDEX(Analysis!$B$71:$L$91, MATCH(B51, Analysis!$A$71:$A$91, 0), MATCH(C51, Analysis!$B$70:$L$70, 0)), "") -> Mild | J51: =IF(ISBLANK(A51),"",WEEKNUM(A51)) -> 18 | K51: =IF(ISBLANK(A51),"",DATE(YEAR(A51),MONTH(A51),DAY(A51))) -> 45779 | L51: =IF(A51="", "", A51 - INT(A51)) -> 0.42273148 | M51: {=IF(L51="","",_xlfn.IFS( AND(L51>=TIME(9,0,0), L51<TIME(16,0,0)),"Morning", AND(L51>=TIME(16,0,0), L51<TIME(23,59,0)),"Evening", L51>=TIME(23,59,0),"Night", L51<TIME(9,0,0),"Night" ))} -> Morning | O51: =IF(N51="ON", _xlfn.IMAGE(E51, 1), "")
A52: 02-May-2025 10:13:26 | B52: PPE | C52: Lucknow | D52: Fuel Farm -NRP (Front) | E52: https://smile-ai-test.s3.ap-south-1.amazonaws.com/content/violation/ppe/frame/40267_20250502T044325_ppe_p.jpg | F52: 0 | G52: =IF(ISBLANK(A52), "", IF(ISBLANK(F52), 0, F52)) -> 0 | H52: =IF(ISBLANK(E52),"",HYPERLINK(E52,"Click here")) -> Click here | I52: =IFERROR(INDEX(Analysis!$B$71:$L$91, MATCH(B52, Analysis!$A$71:$A$91, 0), MATCH(C52, Analysis!$B$70:$L$70, 0)), "") -> Mild | J52: =IF(ISBLANK(A52),"",WEEKNUM(A52)) -> 18 | K52: =IF(ISBLANK(A52),"",DATE(YEAR(A52),MONTH(A52),DAY(A52))) -> 45779 | L52: =IF(A52="", "", A52 - INT(A52)) -> 0.42599537 | M52: {=IF(L52="","",_xlfn.IFS( AND(L52>=TIME(9,0,0), L52<TIME(16,0,0)),"Morning", AND(L52>=TIME(16,0,0), L52<TIME(23,59,0)),"Evening", L52>=TIME(23,59,0),"Night", L52<TIME(9,0,0),"Night" ))} -> Morning | O52: =IF(N52="ON", _xlfn.IMAGE(E52, 1), "")
A53: 02-May-2025 10:15:38 | B53: PPE | C53: Mangalore | D53: Precision approach Y | E53: https://smile-ai-test.s3.ap-south-1.amazonaws.com/content/violation/ppe/frame/11083_20250502T044536_ppe_p.jpg | F53: 0 | G53: =IF(ISBLANK(A53), "", IF(ISBLANK(F53), 0, F53)) -> 0 | H53: =IF(ISBLANK(E53),"",HYPERLINK(E53,"Click here")) -> Click here | I53: =IFERROR(INDEX(Analysis!$B$71:$L$91, MATCH(B53, Analysis!$A$71:$A$91, 0), MATCH(C53, Analysis!$B$70:$L$70, 0)), "") -> Mild | J53: =IF(ISBLANK(A53),"",WEEKNUM(A53)) -> 18 | K53: =IF(ISBLANK(A53),"",DATE(YEAR(A53),MONTH(A53),DAY(A53))) -> 45779 | L53: =IF(A53="", "", A53 - INT(A53)) -> 0.42752315 | M53: {=IF(L53="","",_xlfn.IFS( AND(L53>=TIME(9,0,0), L53<TIME(16,0,0)),"Morning", AND(L53>=TIME(16,0,0), L53<TIME(23,59,0)),"Evening", L53>=TIME(23,59,0),"Night", L53<TIME(9,0,0),"Night" ))} -> Morning | O53: =IF(N53="ON", _xlfn.IMAGE(E53, 1), "")
A54: 02-May-2025 10:15:39 | B54: Work At Height | C54: Ahmedabad | D54: CSD - West Side | E54: https://smile-ai-test.s3.ap-south-1.amazonaws.com/content/violation/wah/frame/59480_20250502T044539_wah_p.jpg | F54: 0 | G54: =IF(ISBLANK(A54), "", IF(ISBLANK(F54), 0, F54)) -> 0 | H54: =IF(ISBLANK(E54),"",HYPERLINK(E54,"Click here")) -> Click here | I54: =IFERROR(INDEX(Analysis!$B$71:$L$91, MATCH(B54, Analysis!$A$71:$A$91, 0), MATCH(C54, Analysis!$B$70:$L$70, 0)), "") -> Severe | J54: =IF(ISBLANK(A54),"",WEEKNUM(A54)) -> 18 | K54: =IF(ISBLANK(A54),"",DATE(YEAR(A54),MONTH(A54),DAY(A54))) -> 45779 | L54: =IF(A54="", "", A54 - INT(A54)) -> 0.42753472 | M54: {=IF(L54="","",_xlfn.IFS( AND(L54>=TIME(9,0,0), L54<TIME(16,0,0)),"Morning", AND(L54>=TIME(16,0,0), L54<TIME(23,59,0)),"Evening", L54>=TIME(23,59,0),"Night", L54<TIME(9,0,0),"Night" ))} -> Morning | O54: =IF(N54="ON", _xlfn.IMAGE(E54, 1), "")
A55: 02-May-2025 10:15:44 | B55: PPE | C55: Lucknow | D55: Fuel Farm -NRP (Front) | E55: https://smile-ai-test.s3.ap-south-1.amazonaws.com/content/violation/ppe/frame/70941_20250502T044544_ppe_p.jpg | F55: 0 | G55: =IF(ISBLANK(A55), "", IF(ISBLANK(F55), 0, F55)) -> 0 | H55: =IF(ISBLANK(E55),"",HYPERLINK(E55,"Click here")) -> Click here | I55: =IFERROR(INDEX(Analysis!$B$71:$L$91, MATCH(B55, Analysis!$A$71:$A$91, 0), MATCH(C55, Analysis!$B$70:$L$70, 0)), "") -> Mild | J55: =IF(ISBLANK(A55),"",WEEKNUM(A55)) -> 18 | K55: =IF(ISBLANK(A55),"",DATE(YEAR(A55),MONTH(A55),DAY(A55))) -> 45779 | L55: =IF(A55="", "", A55 - INT(A55)) -> 0.42759259 | M55: {=IF(L55="","",_xlfn.IFS( AND(L55>=TIME(9,0,0), L55<TIME(16,0,0)),"Morning", AND(L55>=TIME(16,0,0), L55<TIME(23,59,0)),"Evening", L55>=TIME(23,59,0),"Night", L55<TIME(9,0,0),"Night" ))} -> Morning | O55: =IF(N55="ON", _xlfn.IMAGE(E55, 1), "")
A56: 02-May-2025 10:33:29 | B56: PPE | C56: Ahmedabad | D56: Ahmedabad-w | E56: https://smile-ai-test.s3.ap-south-1.amazonaws.com/content/violation/ppe/frame/13774_20250502T050328_ppe_p.jpg | F56: 0 | G56: =IF(ISBLANK(A56), "", IF(ISBLANK(F56), 0, F56)) -> 0 | H56: =IF(ISBLANK(E56),"",HYPERLINK(E56,"Click here")) -> Click here | I56: =IFERROR(INDEX(Analysis!$B$71:$L$91, MATCH(B56, Analysis!$A$71:$A$91, 0), MATCH(C56, Analysis!$B$70:$L$70, 0)), "") -> Mild | J56: =IF(ISBLANK(A56),"",WEEKNUM(A56)) -> 18 | K56: =IF(ISBLANK(A56),"",DATE(YEAR(A56),MONTH(A56),DAY(A56))) -> 45779 | L56: =IF(A56="", "", A56 - INT(A56)) -> 0.43991898 | M56: {=IF(L56="","",_xlfn.IFS( AND(L56>=TIME(9,0,0), L56<TIME(16,0,0)),"Morning", AND(L56>=TIME(16,0,0), L56<TIME(23,59,0)),"Evening", L56>=TIME(23,59,0),"Night", L56<TIME(9,0,0),"Night" ))} -> Morning | O56: =IF(N56="ON", _xlfn.IMAGE(E56, 1), "")
A57: 02-May-2025 10:47:40 | B57: Vehicle Reverse Flagman | C57: Ahmedabad | D57: CSD - East Side | E57: https://smile-ai-test.s3.ap-south-1.amazonaws.com/content/violation/flagman/frame/81734_20250502T051739_flagman_p.jpg | F57: 0 | G57: =IF(ISBLANK(A57), "", IF(ISBLANK(F57), 0, F57)) -> 0 | H57: =IF(ISBLANK(E57),"",HYPERLINK(E57,"Click here")) -> Click here | I57: =IFERROR(INDEX(Analysis!$B$71:$L$91, MATCH(B57, Analysis!$A$71:$A$91, 0), MATCH(C57, Analysis!$B$70:$L$70, 0)), "") -> Severe | J57: =IF(ISBLANK(A57),"",WEEKNUM(A57)) -> 18 | K57: =IF(ISBLANK(A57),"",DATE(YEAR(A57),MONTH(A57),DAY(A57))) -> 45779 | L57: =IF(A57="", "", A57 - INT(A57)) -> 0.44976852 | M57: {=IF(L57="","",_xlfn.IFS( AND(L57>=TIME(9,0,0), L57<TIME(16,0,0)),"Morning", AND(L57>=TIME(16,0,0), L57<TIME(23,59,0)),"Evening", L57>=TIME(23,59,0),"Night", L57<TIME(9,0,0),"Night" ))} -> Morning | O57: =IF(N57="ON", _xlfn.IMAGE(E57, 1), "")
A58: 02-May-2025 11:02:05 | B58: PPE | C58: Ahmedabad | D58: JCPL Plant | E58: https://smile-ai-test.s3.ap-south-1.amazonaws.com/content/violation/ppe/frame/34286_20250502T053205_ppe_p.jpg | F58: 0 | G58: =IF(ISBLANK(A58), "", IF(ISBLANK(F58), 0, F58)) -> 0 | H58: =IF(ISBLANK(E58),"",HYPERLINK(E58,"Click here")) -> Click here | I58: =IFERROR(INDEX(Analysis!$B$71:$L$91, MATCH(B58, Analysis!$A$71:$A$91, 0), MATCH(C58, Analysis!$B$70:$L$70, 0)), "") -> Mild | J58: =IF(ISBLANK(A58),"",WEEKNUM(A58)) -> 18 | K58: =IF(ISBLANK(A58),"",DATE(YEAR(A58),MONTH(A58),DAY(A58))) -> 45779 | L58: =IF(A58="", "", A58 - INT(A58)) -> 0.45978009 | M58: {=IF(L58="","",_xlfn.IFS( AND(L58>=TIME(9,0,0), L58<TIME(16,0,0)),"Morning", AND(L58>=TIME(16,0,0), L58<TIME(23,59,0)),"Evening", L58>=TIME(23,59,0),"Night", L58<TIME(9,0,0),"Night" ))} -> Morning | O58: =IF(N58="ON", _xlfn.IMAGE(E58, 1), "")
A59: 02-May-2025 11:08:08 | B59: Phone At Work | C59: Lucknow | D59: Zone 5 NCC Slab | E59: https://smile-ai-test.s3.ap-south-1.amazonaws.com/content/violation/phone/frame/52942_20250502T053807_phone_p.jpg | F59: 0 | G59: =IF(ISBLANK(A59), "", IF(ISBLANK(F59), 0, F59)) -> 0 | H59: =IF(ISBLANK(E59),"",HYPERLINK(E59,"Click here")) -> Click here | I59: =IFERROR(INDEX(Analysis!$B$71:$L$91, MATCH(B59, Analysis!$A$71:$A$91, 0), MATCH(C59, Analysis!$B$70:$L$70, 0)), "") -> Mild | J59: =IF(ISBLANK(A59),"",WEEKNUM(A59)) -> 18 | K59: =IF(ISBLANK(A59),"",DATE(YEAR(A59),MONTH(A59),DAY(A59))) -> 45779 | L59: =IF(A59="", "", A59 - INT(A59)) -> 0.46398148 | M59: {=IF(L59="","",_xlfn.IFS( AND(L59>=TIME(9,0,0), L59<TIME(16,0,0)),"Morning", AND(L59>=TIME(16,0,0), L59<TIME(23,59,0)),"Evening", L59>=TIME(23,59,0),"Night", L59<TIME(9,0,0),"Night" ))} -> Morning | O59: =IF(N59="ON", _xlfn.IMAGE(E59, 1), "")
A60: 02-May-2025 11:21:19 | B60: Vehicle Reverse Flagman | C60: Ahmedabad | D60: JCPL Plant | E60: https://smile-ai-test.s3.ap-south-1.amazonaws.com/content/violation/flagman/frame/47775_20250502T055118_flagman_p.jpg | F60: 0 | G60: =IF(ISBLANK(A60), "", IF(ISBLANK(F60), 0, F60)) -> 0 | H60: =IF(ISBLANK(E60),"",HYPERLINK(E60,"Click here")) -> Click here | I60: =IFERROR(INDEX(Analysis!$B$71:$L$91, MATCH(B60, Analysis!$A$71:$A$91, 0), MATCH(C60, Analysis!$B$70:$L$70, 0)), "") -> Severe | J60: =IF(ISBLANK(A60),"",WEEKNUM(A60)) -> 18 | K60: =IF(ISBLANK(A60),"",DATE(YEAR(A60),MONTH(A60),DAY(A60))) -> 45779 | L60: =IF(A60="", "", A60 - INT(A60)) -> 0.47313657 | M60: {=IF(L60="","",_xlfn.IFS( AND(L60>=TIME(9,0,0), L60<TIME(16,0,0)),"Morning", AND(L60>=TIME(16,0,0), L60<TIME(23,59,0)),"Evening", L60>=TIME(23,59,0),"Night", L60<TIME(9,0,0),"Night" ))} -> Morning | O60: =IF(N60="ON", _xlfn.IMAGE(E60, 1), "")
A61: 02-May-2025 11:23:10 | B61: Vehicle Reverse Flagman | C61: Ahmedabad | D61: CSD - East Side | E61: https://smile-ai-test.s3.ap-south-1.amazonaws.com/content/violation/flagman/frame/21480_20250502T055309_flagman_p.jpg | F61: 0 | G61: =IF(ISBLANK(A61), "", IF(ISBLANK(F61), 0, F61)) -> 0 | H61: =IF(ISBLANK(E61),"",HYPERLINK(E61,"Click here")) -> Click here | I61: =IFERROR(INDEX(Analysis!$B$71:$L$91, MATCH(B61, Analysis!$A$71:$A$91, 0), MATCH(C61, Analysis!$B$70:$L$70, 0)), "") -> Severe | J61: =IF(ISBLANK(A61),"",WEEKNUM(A61)) -> 18 | K61: =IF(ISBLANK(A61),"",DATE(YEAR(A61),MONTH(A61),DAY(A61))) -> 45779 | L61: =IF(A61="", "", A61 - INT(A61)) -> 0.4744213 | M61: {=IF(L61="","",_xlfn.IFS( AND(L61>=TIME(9,0,0), L61<TIME(16,0,0)),"Morning", AND(L61>=TIME(16,0,0), L61<TIME(23,59,0)),"Evening", L61>=TIME(23,59,0),"Night", L61<TIME(9,0,0),"Night" ))} -> Morning | O61: =IF(N61="ON", _xlfn.IMAGE(E61, 1), "")
A62: 02-May-2025 11:28:22 | B62: PPE | C62: Mumbai | D62: GA Terminal - 03 | E62: https://smile-ai-test.s3.ap-south-1.amazonaws.com/content/violation/ppe/frame/65169_20250502T055821_ppe_p.jpg | F62: 0 | G62: =IF(ISBLANK(A62), "", IF(ISBLANK(F62), 0, F62)) -> 0 | H62: =IF(ISBLANK(E62),"",HYPERLINK(E62,"Click here")) -> Click here | I62: =IFERROR(INDEX(Analysis!$B$71:$L$91, MATCH(B62, Analysis!$A$71:$A$91, 0), MATCH(C62, Analysis!$B$70:$L$70, 0)), "") -> Mild | J62: =IF(ISBLANK(A62),"",WEEKNUM(A62)) -> 18 | K62: =IF(ISBLANK(A62),"",DATE(YEAR(A62),MONTH(A62),DAY(A62))) -> 45779 | L62: =IF(A62="", "", A62 - INT(A62)) -> 0.47803241 | M62: {=IF(L62="","",_xlfn.IFS( AND(L62>=TIME(9,0,0), L62<TIME(16,0,0)),"Morning", AND(L62>=TIME(16,0,0), L62<TIME(23,59,0)),"Evening", L62>=TIME(23,59,0),"Night", L62<TIME(9,0,0),"Night" ))} -> Morning | O62: =IF(N62="ON", _xlfn.IMAGE(E62, 1), "")
A63: 02-May-2025 11:28:38 | B63: Work At Height | C63: Ahmedabad | D63: CISF Barrack | E63: https://smile-ai-test.s3.ap-south-1.amazonaws.com/content/violation/wah/frame/18463_20250502T055837_wah_p.jpg | F63: 0 | G63: =IF(ISBLANK(A63), "", IF(ISBLANK(F63), 0, F63)) -> 0 | H63: =IF(ISBLANK(E63),"",HYPERLINK(E63,"Click here")) -> Click here | I63: =IFERROR(INDEX(Analysis!$B$71:$L$91, MATCH(B63, Analysis!$A$71:$A$91, 0), MATCH(C63, Analysis!$B$70:$L$70, 0)), "") -> Severe | J63: =IF(ISBLANK(A63),"",WEEKNUM(A63)) -> 18 | K63: =IF(ISBLANK(A63),"",DATE(YEAR(A63),MONTH(A63),DAY(A63))) -> 45779 | L63: =IF(A63="", "", A63 - INT(A63)) -> 0.47821759 | M63: {=IF(L63="","",_xlfn.IFS( AND(L63>=TIME(9,0,0), L63<TIME(16,0,0)),"Morning", AND(L63>=TIME(16,0,0), L63<TIME(23,59,0)),"Evening", L63>=TIME(23,59,0),"Night", L63<TIME(9,0,0),"Night" ))} -> Morning | O63: =IF(N63="ON", _xlfn.IMAGE(E63, 1), "")
... A2960: 31-May-2025 23:44:22 | B2960: Welding / Gas cutting | C2960: Guwahati | D2960: City Side HM | E2960: https://smile-ai-test.s3.ap-south-1.amazonaws.com/content/violation/fire/frame/98192_20250531T181421_fire_p.jpg | F2960: 0 | G2960: =IF(ISBLANK(A2960), "", IF(ISBLANK(F2960), 0, F2960)) -> 0 | H2960: =IF(ISBLANK(E2960),"",HYPERLINK(E2960,"Click here")) -> Click here | I2960: =IFERROR(INDEX(Analysis!$B$71:$L$91, MATCH(B2960, Analysis!$A$71:$A$91, 0), MATCH(C2960, Analysis!$B$70:$L$70, 0)), "") -> Mild | J2960: =IF(ISBLANK(A2960),"",WEEKNUM(A2960)) -> 22 | K2960: =IF(ISBLANK(A2960),"",DATE(YEAR(A2960),MONTH(A2960),DAY(A2960))) -> 45808 | L2960: =IF(A2960="", "", A2960 - INT(A2960)) -> 0.98914352 | M2960: {=IF(L2960="","",_xlfn.IFS( AND(L2960>=TIME(9,0,0), L2960<TIME(16,0,0)),"Morning", AND(L2960>=TIME(16,0,0), L2960<TIME(23,59,0)),"Evening", L2960>=TIME(23,59,0),"Night", L2960<TIME(9,0,0),"Night" ))} -> Evening | O2960: =IF(N2960="ON", _xlfn.IMAGE(E2960, 1), "")
G2961: =IF(ISBLANK(A2961), "", IF(ISBLANK(F2961), 0, F2961)) | H2961: =IF(ISBLANK(E2961),"",HYPERLINK(E2961,"Click here")) | I2961: =IFERROR(INDEX(Analysis!$B$71:$L$91, MATCH(B2961, Analysis!$A$71:$A$91, 0), MATCH(C2961, Analysis!$B$70:$L$70, 0)), "") | J2961: =IF(ISBLANK(A2961),"",WEEKNUM(A2961)) | K2961: =IF(ISBLANK(A2961),"",DATE(YEAR(A2961),MONTH(A2961),DAY(A2961))) | L2961: =IF(A2961="", "", A2961 - INT(A2961)) | M2961: {=IF(L2961="","",_xlfn.IFS( AND(L2961>=TIME(9,0,0), L2961<TIME(16,0,0)),"Morning", AND(L2961>=TIME(16,0,0), L2961<TIME(23,59,0)),"Evening", L2961>=TIME(23,59,0),"Night", L2961<TIME(9,0,0),"Night" ))} | O2961: =IF(N2961="ON", _xlfn.IMAGE(E2961, 1), "")
G2962: =IF(ISBLANK(A2962), "", IF(ISBLANK(F2962), 0, F2962)) | H2962: =IF(ISBLANK(E2962),"",HYPERLINK(E2962,"Click here")) | I2962: =IFERROR(INDEX(Analysis!$B$71:$L$91, MATCH(B2962, Analysis!$A$71:$A$91, 0), MATCH(C2962, Analysis!$B$70:$L$70, 0)), "") | J2962: =IF(ISBLANK(A2962),"",WEEKNUM(A2962)) | K2962: =IF(ISBLANK(A2962),"",DATE(YEAR(A2962),MONTH(A2962),DAY(A2962))) | L2962: =IF(A2962="", "", A2962 - INT(A2962)) | M2962: {=IF(L2962="","",_xlfn.IFS( AND(L2962>=TIME(9,0,0), L2962<TIME(16,0,0)),"Morning", AND(L2962>=TIME(16,0,0), L2962<TIME(23,59,0)),"Evening", L2962>=TIME(23,59,0),"Night", L2962<TIME(9,0,0),"Night" ))} | O2962: =IF(N2962="ON", _xlfn.IMAGE(E2962, 1), "")
G2963: =IF(ISBLANK(A2963), "", IF(ISBLANK(F2963), 0, F2963)) | H2963: =IF(ISBLANK(E2963),"",HYPERLINK(E2963,"Click here")) | I2963: =IFERROR(INDEX(Analysis!$B$71:$L$91, MATCH(B2963, Analysis!$A$71:$A$91, 0), MATCH(C2963, Analysis!$B$70:$L$70, 0)), "") | J2963: =IF(ISBLANK(A2963),"",WEEKNUM(A2963)) | K2963: =IF(ISBLANK(A2963),"",DATE(YEAR(A2963),MONTH(A2963),DAY(A2963))) | L2963: =IF(A2963="", "", A2963 - INT(A2963)) | M2963: {=IF(L2963="","",_xlfn.IFS( AND(L2963>=TIME(9,0,0), L2963<TIME(16,0,0)),"Morning", AND(L2963>=TIME(16,0,0), L2963<TIME(23,59,0)),"Evening", L2963>=TIME(23,59,0),"Night", L2963<TIME(9,0,0),"Night" ))} | O2963: =IF(N2963="ON", _xlfn.IMAGE(E2963, 1), "")
G2964: =IF(ISBLANK(A2964), "", IF(ISBLANK(F2964), 0, F2964)) | H2964: =IF(ISBLANK(E2964),"",HYPERLINK(E2964,"Click here")) | I2964: =IFERROR(INDEX(Analysis!$B$71:$L$91, MATCH(B2964, Analysis!$A$71:$A$91, 0), MATCH(C2964, Analysis!$B$70:$L$70, 0)), "") | J2964: =IF(ISBLANK(A2964),"",WEEKNUM(A2964)) | K2964: =IF(ISBLANK(A2964),"",DATE(YEAR(A2964),MONTH(A2964),DAY(A2964))) | L2964: =IF(A2964="", "", A2964 - INT(A2964)) | M2964: {=IF(L2964="","",_xlfn.IFS( AND(L2964>=TIME(9,0,0), L2964<TIME(16,0,0)),"Morning", AND(L2964>=TIME(16,0,0), L2964<TIME(23,59,0)),"Evening", L2964>=TIME(23,59,0),"Night", L2964<TIME(9,0,0),"Night" ))} | O2964: =IF(N2964="ON", _xlfn.IMAGE(E2964, 1), "")
...

Sheet Analysis
C2: Violation Type | D2: Count of violations | F2: Violation Type | G2: Count of violations
C3: {=_xlfn.LET( _xlpm.rawDataRange, 'Raw Data'!B2:B5000, _xlpm.nonEmptyCount, COUNTIF(_xlpm.rawDataRange, "<>"), IF( _xlpm.nonEmptyCount = 0, "", _xlfn.LET( _xlpm.rawData, _xlfn._xlws.FILTER(_xlpm.rawDataRange, _xlpm.rawDataRange<>""), _xlpm.uniqueVals, _xlfn.UNIQUE(_xlpm.rawData), _xlpm.counts, COUNTIF(_xlpm.rawDataRange, _xlpm.uniqueVals), _xlpm.sortedData, _xlfn.SORTBY(_xlfn.HSTACK(_xlpm.uniqueVals, _xlpm.counts), _xlpm.counts, -1), _xlpm.sortedData ) ) )} -> PPE | D3: 2261 | F3: =IF(C3="", "", C3) -> PPE | G3: =IF(D3="", "", D3) -> 2261
C4: Vehicle Reverse Flagman | D4: 232 | F4: =IF(C4="", "", C4) -> Vehicle Reverse Flagman | G4: =IF(D4="", "", D4) -> 232
C5: Welding / Gas cutting | D5: 150 | F5: =IF(C5="", "", C5) -> Welding / Gas cutting | G5: =IF(D5="", "", D5) -> 150
C6: Work At Height | D6: 142 | F6: =IF(C6="", "", C6) -> Work At Height | G6: =IF(D6="", "", D6) -> 142
C7: Phone At Work | D7: 78 | F7: =IF(C7="", "", C7) -> Phone At Work | G7: =IF(D7="", "", D7) -> 78
C8: Crowd Gathering | D8: 48 | F8: =IF(C8="", "", C8) -> Crowd Gathering | G8: =IF(D8="", "", D8) -> 48
C9: Unconscious/Resting | D9: 37 | F9: =IF(C9="", "", C9) -> Unconscious/Resting | G9: =IF(D9="", "", D9) -> 37
C10: Unauthorized Access | D10: 10 | F10: =IF(C10="", "", C10) -> Unauthorized Access | G10: =IF(D10="", "", D10) -> 10
C11: Lifting and Hoisting | D11: 1 | F11: =IF(C11="", "", C11) -> Lifting and Hoisting | G11: =IF(D11="", "", D11) -> 1
F12: =IF(C12="", "", C12) | G12: =IF(D12="", "", D12)
F13: =IF(C13="", "", C13) | G13: =IF(D13="", "", D13)
F14: =IF(C14="", "", C14) | G14: =IF(D14="", "", D14)
F15: =IF(C15="", "", C15) | G15: =IF(D15="", "", D15)
F16: =IF(C16="", "", C16) | G16: =IF(D16="", "", D16)
F17: =IF(C17="", "", C17) | G17: =IF(D17="", "", D17)
F18: =IF(C18="", "", C18) | G18: =IF(D18="", "", D18)
F19: =IF(C19="", "", C19) | G19: =IF(D19="", "", D19)
F20: =IF(C20="", "", C20) | G20: =IF(D20="", "", D20)
F21: =IF(C21="", "", C21) | G21: =IF(D21="", "", D21)
C27: TOTAL | D27: =SUM(D3:D26) -> 2959
A30: STATE | B30: VIO
A31: Assam | B31: =F42 -> 227
A32: Gujarat | B32: =F43 -> 421
A33: Karnataka | B33: =F44 -> 554
A34: Rajasthan | B34: =F45 -> 28
A35: Kerala | B35: =F46 -> 437
A36: Uttar Pradesh | B36: =F47 -> 754
A37: Maharashtra(Mumbai) | B37: =F48 -> 278
A38: Maharashtra(Navimumbai) | B38: =F49 -> 260
D40: =SUM(D42:D51) -> 2489 | E40: =SUM(E42:E51) -> 470 | F40: =SUM(F42:F51) -> 2959 | L40: =SUM(L42:M51) -> 41
A41: locations | C41: Locations | D41: Less severe violations | E41: More severe violations | F41: total violations | G41: no of day | H41: Daily Avg | I41: Total Cameras | J41: Per camera avg | K41: Unresolved | L41: Resolved | M41: Rejected | N41: locations | O41: percentage | P41: 1-total | Q41: TOTAL
A42: =C42 -> Lucknow | C42: {=_xlfn.LET( _xlpm.rawC, 'Raw Data'!C2:C5000, _xlpm.rawI, 'Raw Data'!I2:I5000, _xlpm.rawJ, 'Raw Data'!K2:K5000, _xlpm.nonEmptyCount, COUNTIF(_xlpm.rawC, "<>"), IF(_xlpm.nonEmptyCount = 0, "", _xlfn.LET( _xlpm.uniqueC, _xlfn.UNIQUE(_xlfn._xlws.FILTER(_xlpm.rawC, _xlpm.rawC <> "")), _xlpm.mildCount, _xlfn.BYROW(_xlpm.uniqueC, _xlfn.LAMBDA(_xlpm.c, SUMPRODUCT((_xlpm.rawC = _xlpm.c) * (_xlpm.rawI = "Mild")) )), _xlpm.severeCount, _xlfn.BYROW(_xlpm.uniqueC, _xlfn.LAMBDA(_xlpm.c, SUMPRODUCT((_xlpm.rawC = _xlpm.c) * (_xlpm.rawI = "Severe")) )), _xlpm.totalCategory, _xlfn.BYROW(_xlfn.SEQUENCE(ROWS(_xlpm.uniqueC)), _xlfn.LAMBDA(_xlpm.i, INDEX(_xlpm.mildCount, _xlpm.i) + INDEX(_xlpm.severeCount, _xlpm.i) )), _xlpm.countJ, _xlfn.BYROW(_xlpm.uniqueC, _xlfn.LAMBDA(_xlpm.c, SUM(--(_xlfn.UNIQUE(_xlfn._xlws.FILTER(_xlpm.rawJ, _xlpm.rawC = _xlpm.c)) <> "")) )), _xlpm.ratio, _xlfn.BYROW(_xlfn.SEQUENCE(ROWS(_xlpm.uniqueC)), _xlfn.LAMBDA(_xlpm.i, _xlfn.LET( _xlpm.total, INDEX(_xlpm.totalCategory, _xlpm.i), _xlpm.cnt, INDEX(_xlpm.countJ, _xlpm.i), IF(_xlpm.cnt = 0, "", ROUND(_xlpm.total / _xlpm.cnt, 0)) ) )), _xlfn.HSTACK(_xlpm.uniqueC, _xlpm.mildCount, _xlpm.severeCount, _xlpm.totalCategory, _xlpm.countJ, _xlpm.ratio) ) ) )} -> Lucknow | D42: 158 | E42: 69 | F42: 227 | G42: 29 | H42: 8 | I42: {=IF(OR(C42="", COUNTA(_xlfn._xlws.FILTER('Raw Data'!D2:D5000, 'Raw Data'!C2:C5000=C42))=0), " ", COUNTA(_xlfn.UNIQUE(_xlfn._xlws.FILTER('Raw Data'!D2:D5000, ('Raw Data'!C2:C5000=C42)*('Raw Data'!D2:D5000<>"")))))} -> 5 | J42: {=_xlfn.LET( _xlpm.f, F42:F57, _xlpm.i, I42:I57, _xlpm.h, H42:H57, _xlpm.nonEmptyF, COUNTIF(_xlpm.f, "<>"), IF(_xlpm.nonEmptyF = 0, "", _xlfn.LET( _xlpm.valid, (_xlpm.f <> "") * (_xlpm.i <> "") * (_xlpm.h <> ""), _xlpm.filteredF, _xlfn._xlws.FILTER(_xlpm.f, _xlpm.valid), _xlpm.filteredI, _xlfn._xlws.FILTER(_xlpm.i, _xlpm.valid), _xlpm.filteredH, _xlfn._xlws.FILTER(_xlpm.h, _xlpm.valid), _xlpm.safeI, IF(_xlpm.filteredI = 0, 1, _xlpm.filteredI), _xlpm.safeH, IF(_xlpm.filteredH = 0, 1, _xlpm.filteredH), ROUND(_xlpm.filteredF / _xlpm.safeI / _xlpm.safeH, 0) ) ) )} -> 6 | K42: {=_xlfn.LET( _xlpm.rawC, 'Raw Data'!C2:C5000, _xlpm.rawG, 'Raw Data'!G2:G5000, _xlpm.nonEmptyCount, COUNTIF(_xlpm.rawC, "<>"), IF( _xlpm.nonEmptyCount = 0, "", _xlfn.LET( _xlpm.uniqueSortedC, _xlfn._xlws.SORT(_xlfn.UNIQUE(_xlfn._xlws.FILTER(_xlpm.rawC, _xlpm.rawC <> ""))), COUNTIFS(_xlpm.rawC, _xlpm.uniqueSortedC, _xlpm.rawG, 0) ) ) )} -> 414 | L42: {=_xlfn.LET( _xlpm.rawC, 'Raw Data'!C2:C5000, _xlpm.rawG, 'Raw Data'!G2:G5000, _xlpm.nonEmptyCount, COUNTIF(_xlpm.rawC, "<>"), IF( _xlpm.nonEmptyCount = 0, "", _xlfn.LET( _xlpm.uniqueSortedC, _xlfn._xlws.SORT(_xlfn.UNIQUE(_xlfn._xlws.FILTER(_xlpm.rawC, _xlpm.rawC <> ""))), COUNTIFS(_xlpm.rawC, _xlpm.uniqueSortedC, _xlpm.rawG, 1) ) ) )} -> 0 | M42: {=_xlfn.LET( _xlpm.rawC, 'Raw Data'!C2:C5000, _xlpm.rawG, 'Raw Data'!G2:G5000, _xlpm.nonEmptyCount, COUNTIF(_xlpm.rawC, "<>"), IF( _xlpm.nonEmptyCount = 0, "", _xlfn.LET( _xlpm.uniqueSortedC, _xlfn._xlws.SORT(_xlfn.UNIQUE(_xlfn._xlws.FILTER(_xlpm.rawC, _xlpm.rawC <> ""))), COUNTIFS(_xlpm.rawC, _xlpm.uniqueSortedC, _xlpm.rawG, 2) ) ) )} -> 7 | N42: {=IF(C42="", "", _xlfn.TEXTJOIN("", TRUE, IF(ISNUMBER(--MID(C42, ROW(INDIRECT("1:" & LEN(C42))), 1)), "", MID(C42, ROW(INDIRECT("1:" & LEN(C42))), 1))))} -> Lucknow | O42: =IF(F42="", "", ROUND((F42/100)*L42, 0) & "%") -> 0% | P42: {=IF(O42:O51="", "", Q42:Q51 - O42:O51)} -> 1 | Q42: 1
A43: =C43 -> Ahmedabad | C43: Ahmedabad | D43: 232 | E43: 189 | F43: 421 | G43: 30 | H43: 14 | I43: {=IF(OR(C43="", COUNTA(_xlfn._xlws.FILTER('Raw Data'!D3:D5001, 'Raw Data'!C3:C5001=C43))=0), " ", COUNTA(_xlfn.UNIQUE(_xlfn._xlws.FILTER('Raw Data'!D3:D5001, ('Raw Data'!C3:C5001=C43)*('Raw Data'!D3:D5001<>"")))))} -> 10 | J43: 3 | K43: 548 | L43: 0 | M43: 6 | N43: {=IF(C43="", "", _xlfn.TEXTJOIN("", TRUE, IF(ISNUMBER(--MID(C43, ROW(INDIRECT("1:" & LEN(C43))), 1)), "", MID(C43, ROW(INDIRECT("1:" & LEN(C43))), 1))))} -> Ahmedabad | O43: =IF(F43="", "", ROUND((F43/100)*L43, 0) & "%") -> 0% | P43: 1 | Q43: 1
A44: =C44 -> Guwahati | C44: Guwahati | D44: 454 | E44: 100 | F44: 554 | G44: 31 | H44: 18 | I44: {=IF(OR(C44="", COUNTA(_xlfn._xlws.FILTER('Raw Data'!D4:D5002, 'Raw Data'!C4:C5002=C44))=0), " ", COUNTA(_xlfn.UNIQUE(_xlfn._xlws.FILTER('Raw Data'!D4:D5002, ('Raw Data'!C4:C5002=C44)*('Raw Data'!D4:D5002<>"")))))} -> 10 | J44: 3 | K44: 20 | L44: 0 | M44: 8 | N44: {=IF(C44="", "", _xlfn.TEXTJOIN("", TRUE, IF(ISNUMBER(--MID(C44, ROW(INDIRECT("1:" & LEN(C44))), 1)), "", MID(C44, ROW(INDIRECT("1:" & LEN(C44))), 1))))} -> Guwahati | O44: =IF(F44="", "", ROUND((F44/100)*L44, 0) & "%") -> 0% | P44: 1 | Q44: 1
A45: =C45 -> Jaipur | C45: Jaipur | D45: 26 | E45: 2 | F45: 28 | G45: 8 | H45: 4 | I45: {=IF(OR(C45="", COUNTA(_xlfn._xlws.FILTER('Raw Data'!D5:D5003, 'Raw Data'!C5:C5003=C45))=0), " ", COUNTA(_xlfn.UNIQUE(_xlfn._xlws.FILTER('Raw Data'!D5:D5003, ('Raw Data'!C5:C5003=C45)*('Raw Data'!D5:D5003<>"")))))} -> 4 | J45: 2 | K45: 224 | L45: 0 | M45: 3 | N45: {=IF(C45="", "", _xlfn.TEXTJOIN("", TRUE, IF(ISNUMBER(--MID(C45, ROW(INDIRECT("1:" & LEN(C45))), 1)), "", MID(C45, ROW(INDIRECT("1:" & LEN(C45))), 1))))} -> Jaipur | O45: =IF(F45="", "", ROUND((F45/100)*L45, 0) & "%") -> 0% | P45: 1 | Q45: 1
A46: =C46 -> Thiruvananthapuram | C46: Thiruvananthapuram | D46: 420 | E46: 17 | F46: 437 | G46: 29 | H46: 15 | I46: {=IF(OR(C46="", COUNTA(_xlfn._xlws.FILTER('Raw Data'!D6:D5004, 'Raw Data'!C6:C5004=C46))=0), " ", COUNTA(_xlfn.UNIQUE(_xlfn._xlws.FILTER('Raw Data'!D6:D5004, ('Raw Data'!C6:C5004=C46)*('Raw Data'!D6:D5004<>"")))))} -> 4 | J46: 7 | K46: 741 | L46: 0 | M46: 13 | N46: {=IF(C46="", "", _xlfn.TEXTJOIN("", TRUE, IF(ISNUMBER(--MID(C46, ROW(INDIRECT("1:" & LEN(C46))), 1)), "", MID(C46, ROW(INDIRECT("1:" & LEN(C46))), 1))))} -> Thiruvananthapuram | O46: =IF(F46="", "", ROUND((F46/100)*L46, 0) & "%") -> 0% | P46: 1 | Q46: 1
A47: =C47 -> Mangalore | C47: Mangalore | D47: 711 | E47: 43 | F47: 754 | G47: 29 | H47: 26 | I47: {=IF(OR(C47="", COUNTA(_xlfn._xlws.FILTER('Raw Data'!D7:D5005, 'Raw Data'!C7:C5005=C47))=0), " ", COUNTA(_xlfn.UNIQUE(_xlfn._xlws.FILTER('Raw Data'!D7:D5005, ('Raw Data'!C7:C5005=C47)*('Raw Data'!D7:D5005<>"")))))} -> 9 | J47: 3 | K47: 278 | L47: 0 | M47: 0 | N47: {=IF(C47="", "", _xlfn.TEXTJOIN("", TRUE, IF(ISNUMBER(--MID(C47, ROW(INDIRECT("1:" & LEN(C47))), 1)), "", MID(C47, ROW(INDIRECT("1:" & LEN(C47))), 1))))} -> Mangalore | O47: =IF(F47="", "", ROUND((F47/100)*L47, 0) & "%") -> 0% | P47: 1 | Q47: 1
A48: =C48 -> Mumbai | C48: Mumbai | D48: 257 | E48: 21 | F48: 278 | G48: 28 | H48: 10 | I48: {=IF(OR(C48="", COUNTA(_xlfn._xlws.FILTER('Raw Data'!D8:D5006, 'Raw Data'!C8:C5006=C48))=0), " ", COUNTA(_xlfn.UNIQUE(_xlfn._xlws.FILTER('Raw Data'!D8:D5006, ('Raw Data'!C8:C5006=C48)*('Raw Data'!D8:D5006<>"")))))} -> 8 | J48: 3 | K48: 260 | L48: 0 | M48: 0 | N48: {=IF(C48="", "", _xlfn.TEXTJOIN("", TRUE, IF(ISNUMBER(--MID(C48, ROW(INDIRECT("1:" & LEN(C48))), 1)), "", MID(C48, ROW(INDIRECT("1:" & LEN(C48))), 1))))} -> Mumbai | O48: =IF(F48="", "", ROUND((F48/100)*L48, 0) & "%") -> 0% | P48: 1 | Q48: 1
A49: =C49 -> Navimumbai | C49: Navimumbai | D49: 231 | E49: 29 | F49: 260 | G49: 5 | H49: 52 | I49: {=IF(OR(C49="", COUNTA(_xlfn._xlws.FILTER('Raw Data'!D9:D5007, 'Raw Data'!C9:C5007=C49))=0), " ", COUNTA(_xlfn.UNIQUE(_xlfn._xlws.FILTER('Raw Data'!D9:D5007, ('Raw Data'!C9:C5007=C49)*('Raw Data'!D9:D5007<>"")))))} -> 10 | J49: 1 | K49: 433 | L49: 0 | M49: 4 | N49: {=IF(C49="", "", _xlfn.TEXTJOIN("", TRUE, IF(ISNUMBER(--MID(C49, ROW(INDIRECT("1:" & LEN(C49))), 1)), "", MID(C49, ROW(INDIRECT("1:" & LEN(C49))), 1))))} -> Navimumbai | O49: =IF(F49="", "", ROUND((F49/100)*L49, 0) & "%") -> 0% | P49: 1 | Q49: 1
...

Sheet final report sheet
AC4: Locations | AD4: Guwahati | AE4: Ahmedabad | AF4: Mangalore | AG4: Jaipur | AH4: Thiruvananthapuram | AI4: Lucknow | AJ4: Mumbai | AK4: Navimumbai
AC5: Violation Type | AD5: Count of violation
AC6: PPE | AD6: =COUNTIFS('Raw Data'!$C$2:$C$5000,$AD$4, 'Raw Data'!$B$2:$B$5000,AC6) -> 340 | AE6: =COUNTIFS('Raw Data'!$C$2:$C$5000,$AE$4, 'Raw Data'!$B$2:$B$5000,AC6) -> 228 | AF6: =COUNTIFS('Raw Data'!$C$2:$C$5000,$AF$4, 'Raw Data'!$B$2:$B$5000,AC6) -> 667 | AG6: =COUNTIFS('Raw Data'!$C$2:$C$5000,$AG$4, 'Raw Data'!$B$2:$B$5000,AC6) -> 24 | AH6: =COUNTIFS('Raw Data'!$C$2:$C$5000,$AH$4, 'Raw Data'!$B$2:$B$5000,AC6) -> 412 | AI6: =COUNTIFS('Raw Data'!$C$2:$C$5000,$AI$4, 'Raw Data'!$B$2:$B$5000,AC6) -> 123 | AJ6: =COUNTIFS('Raw Data'!$C$2:$C$5000,$AJ$4, 'Raw Data'!$B$2:$B$5000,AC6) -> 237 | AK6: =COUNTIFS('Raw Data'!$C$2:$C$5000,$AK$4, 'Raw Data'!$B$2:$B$5000,AC7) -> 1
AC7: Phone At Work | AD7: =COUNTIFS('Raw Data'!$C$2:$C$5000,$AD$4, 'Raw Data'!$B$2:$B$5000,AC7) -> 0 | AE7: =COUNTIFS('Raw Data'!$C$2:$C$5000,$AE$4, 'Raw Data'!$B$2:$B$5000,AC7) -> 0 | AF7: =COUNTIFS('Raw Data'!$C$2:$C$5000,$AF$4, 'Raw Data'!$B$2:$B$5000,AC7) -> 43 | AG7: =COUNTIFS('Raw Data'!$C$2:$C$1000,$AG$4, 'Raw Data'!$B$2:$B$1000,AC7) -> 1 | AH7: =COUNTIFS('Raw Data'!$C$2:$C$5000,$AH$4, 'Raw Data'!$B$2:$B$5000,AC7) -> 8 | AI7: =COUNTIFS('Raw Data'!$C$2:$C$5000,$AI$4, 'Raw Data'!$B$2:$B$5000,AC7) -> 12 | AJ7: =COUNTIFS('Raw Data'!$C$2:$C$5000,$AJ$4, 'Raw Data'!$B$2:$B$5000,AC7) -> 12 | AK7: =COUNTIFS('Raw Data'!$C$2:$C$5000,$AK$4, 'Raw Data'!$B$2:$B$5000,AC8) -> 0
AC8: Welding / Gas cutting | AD8: =COUNTIFS('Raw Data'!$C$2:$C$5000,$AD$4, 'Raw Data'!$B$2:$B$5000,AC8) -> 114 | AE8: =COUNTIFS('Raw Data'!$C$2:$C$5000,$AE$4, 'Raw Data'!$B$2:$B$5000,AC8) -> 4 | AF8: =COUNTIFS('Raw Data'!$C$2:$C$5000,$AF$4, 'Raw Data'!$B$2:$B$5000,AC8) -> 1 | AG8: =COUNTIFS('Raw Data'!$C$2:$C$1000,$AG$4, 'Raw Data'!$B$2:$B$1000,AC8) -> 0 | AH8: =COUNTIFS('Raw Data'!$C$2:$C$5000,$AH$4, 'Raw Data'!$B$2:$B$5000,AC8) -> 0 | AI8: =COUNTIFS('Raw Data'!$C$2:$C$5000,$AI$4, 'Raw Data'!$B$2:$B$5000,AC8) -> 23 | AJ8: =COUNTIFS('Raw Data'!$C$2:$C$5000,$AJ$4, 'Raw Data'!$B$2:$B$5000,AC8) -> 8 | AK8: =COUNTIFS('Raw Data'!$C$2:$C$5000,$AK$4, 'Raw Data'!$B$2:$B$5000,AC9) -> 0
AC9: Lifting and Hoisting | AD9: =COUNTIFS('Raw Data'!$C$2:$C$5000,$AD$4, 'Raw Data'!$B$2:$B$5000,AC9) -> 0 | AE9: =COUNTIFS('Raw Data'!$C$2:$C$5000,$AE$4, 'Raw Data'!$B$2:$B$5000,AC9) -> 0 | AF9: =COUNTIFS('Raw Data'!$C$2:$C$5000,$AF$4, 'Raw Data'!$B$2:$B$5000,AC9) -> 0 | AG9: =COUNTIFS('Raw Data'!$C$2:$C$1000,$AG$4, 'Raw Data'!$B$2:$B$1000,AC9) -> 0 | AH9: =COUNTIFS('Raw Data'!$C$2:$C$5000,$AH$4, 'Raw Data'!$B$2:$B$5000,AC9) -> 0 | AI9: =COUNTIFS('Raw Data'!$C$2:$C$5000,$AI$4, 'Raw Data'!$B$2:$B$5000,AC9) -> 0 | AJ9: =COUNTIFS('Raw Data'!$C$2:$C$5000,$AJ$4, 'Raw Data'!$B$2:$B$5000,AC9) -> 1 | AK9: =COUNTIFS('Raw Data'!$C$2:$C$5000,$AK$4, 'Raw Data'!$B$2:$B$5000,AC10) -> 0
AC10: Unconscious/Resting | AD10: =COUNTIFS('Raw Data'!$C$2:$C$5000,$AD$4, 'Raw Data'!$B$2:$B$5000,AC10) -> 20 | AE10: =COUNTIFS('Raw Data'!$C$2:$C$5000,$AE$4, 'Raw Data'!$B$2:$B$5000,AC10) -> 13 | AF10: =COUNTIFS('Raw Data'!$C$2:$C$5000,$AF$4, 'Raw Data'!$B$2:$B$5000,AC10) -> 2 | AG10: =COUNTIFS('Raw Data'!$C$2:$C$1000,$AG$4, 'Raw Data'!$B$2:$B$1000,AC10) -> 0 | AH10: =COUNTIFS('Raw Data'!$C$2:$C$5000,$AH$4, 'Raw Data'!$B$2:$B$5000,AC10) -> 0 | AI10: =COUNTIFS('Raw Data'!$C$2:$C$5000,$AI$4, 'Raw Data'!$B$2:$B$5000,AC10) -> 0 | AJ10: =COUNTIFS('Raw Data'!$C$2:$C$5000,$AJ$4, 'Raw Data'!$B$2:$B$5000,AC10) -> 2 | AK10: =COUNTIFS('Raw Data'!$C$2:$C$5000,$AK$4, 'Raw Data'!$B$2:$B$5000,AC11) -> 10
AC11: Crowd Gathering | AD11: =COUNTIFS('Raw Data'!$C$2:$C$5000,$AD$4, 'Raw Data'!$B$2:$B$5000,AC11) -> 0 | AE11: =COUNTIFS('Raw Data'!$C$2:$C$5000,$AE$4, 'Raw Data'!$B$2:$B$5000,AC11) -> 0 | AF11: =COUNTIFS('Raw Data'!$C$2:$C$5000,$AF$4, 'Raw Data'!$B$2:$B$5000,AC11) -> 2 | AG11: =COUNTIFS('Raw Data'!$C$2:$C$1000,$AG$4, 'Raw Data'!$B$2:$B$1000,AC11) -> 0 | AH11: =COUNTIFS('Raw Data'!$C$2:$C$5000,$AH$4, 'Raw Data'!$B$2:$B$5000,AC11) -> 7 | AI11: =COUNTIFS('Raw Data'!$C$2:$C$5000,$AI$4, 'Raw Data'!$B$2:$B$5000,AC11) -> 18 | AJ11: =COUNTIFS('Raw Data'!$C$2:$C$5000,$AJ$4, 'Raw Data'!$B$2:$B$5000,AC11) -> 11 | AK11: =COUNTIFS('Raw Data'!$C$2:$C$5000,$AK$4, 'Raw Data'!$B$2:$B$5000,AC12) -> 0
AC12: Smoking | AD12: =COUNTIFS('Raw Data'!$C$2:$C$5000,$AD$4, 'Raw Data'!$B$2:$B$5000,AC12) -> 0 | AE12: =COUNTIFS('Raw Data'!$C$2:$C$5000,$AE$4, 'Raw Data'!$B$2:$B$5000,AC12) -> 0 | AF12: =COUNTIFS('Raw Data'!$C$2:$C$5000,$AF$4, 'Raw Data'!$B$2:$B$5000,AC12) -> 0 | AG12: =COUNTIFS('Raw Data'!$C$2:$C$1000,$AG$4, 'Raw Data'!$B$2:$B$1000,AC12) -> 0 | AH12: =COUNTIFS('Raw Data'!$C$2:$C$5000,$AH$4, 'Raw Data'!$B$2:$B$5000,AC12) -> 0 | AI12: =COUNTIFS('Raw Data'!$C$2:$C$5000,$AI$4, 'Raw Data'!$B$2:$B$5000,AC12) -> 0 | AJ12: =COUNTIFS('Raw Data'!$C$2:$C$5000,$AJ$4, 'Raw Data'!$B$2:$B$5000,AC12) -> 0 | AK12: =COUNTIFS('Raw Data'!$C$2:$C$5000,$AK$4, 'Raw Data'!$B$2:$B$5000,AC13) -> 0
AC13: Unauthorized Access | AD13: =COUNTIFS('Raw Data'!$C$2:$C$5000,$AD$4, 'Raw Data'!$B$2:$B$5000,AC13) -> 8 | AE13: =COUNTIFS('Raw Data'!$C$2:$C$5000,$AE$4, 'Raw Data'!$B$2:$B$5000,AC13) -> 2 | AF13: =COUNTIFS('Raw Data'!$C$2:$C$5000,$AF$4, 'Raw Data'!$B$2:$B$5000,AC13) -> 0 | AG13: =COUNTIFS('Raw Data'!$C$2:$C$1000,$AG$4, 'Raw Data'!$B$2:$B$1000,AC13) -> 0 | AH13: =COUNTIFS('Raw Data'!$C$2:$C$5000,$AH$4, 'Raw Data'!$B$2:$B$5000,AC13) -> 0 | AI13: =COUNTIFS('Raw Data'!$C$2:$C$5000,$AI$4, 'Raw Data'!$B$2:$B$5000,AC13) -> 0 | AJ13: =COUNTIFS('Raw Data'!$C$2:$C$5000,$AJ$4, 'Raw Data'!$B$2:$B$5000,AC13) -> 0 | AK13: =COUNTIFS('Raw Data'!$C$2:$C$5000,$AK$4, 'Raw Data'!$B$2:$B$5000,AC14) -> 1
AC14: Vehicle Reverse Flagman | AD14: =COUNTIFS('Raw Data'!$C$2:$C$5000,$AD$4, 'Raw Data'!$B$2:$B$5000,AC14) -> 33 | AE14: =COUNTIFS('Raw Data'!$C$2:$C$5000,$AE$4, 'Raw Data'!$B$2:$B$5000,AC14) -> 101 | AF14: =COUNTIFS('Raw Data'!$C$2:$C$5000,$AF$4, 'Raw Data'!$B$2:$B$5000,AC14) -> 37 | AG14: =COUNTIFS('Raw Data'!$C$2:$C$1000,$AG$4, 'Raw Data'!$B$2:$B$1000,AC14) -> 1 | AH14: =COUNTIFS('Raw Data'!$C$2:$C$5000,$AH$4, 'Raw Data'!$B$2:$B$5000,AC14) -> 8 | AI14: =COUNTIFS('Raw Data'!$C$2:$C$5000,$AI$4, 'Raw Data'!$B$2:$B$5000,AC14) -> 49 | AJ14: =COUNTIFS('Raw Data'!$C$2:$C$5000,$AJ$4, 'Raw Data'!$B$2:$B$5000,AC14) -> 2 | AK14: =COUNTIFS('Raw Data'!$C$2:$C$5000,$AK$4, 'Raw Data'!$B$2:$B$5000,AC15) -> 18
AC15: Work At Height | AD15: =COUNTIFS('Raw Data'!$C$2:$C$5000,$AD$4, 'Raw Data'!$B$2:$B$5000,AC15) -> 39 | AE15: =COUNTIFS('Raw Data'!$C$2:$C$5000,$AE$4, 'Raw Data'!$B$2:$B$5000,AC15) -> 73 | AF15: =COUNTIFS('Raw Data'!$C$2:$C$5000,$AF$4, 'Raw Data'!$B$2:$B$5000,AC15) -> 2 | AG15: =COUNTIFS('Raw Data'!$C$2:$C$1000,$AG$4, 'Raw Data'!$B$2:$B$1000,AC15) -> 1 | AH15: =COUNTIFS('Raw Data'!$C$2:$C$5000,$AH$4, 'Raw Data'!$B$2:$B$5000,AC15) -> 2 | AI15: =COUNTIFS('Raw Data'!$C$2:$C$5000,$AI$4, 'Raw Data'!$B$2:$B$5000,AC15) -> 2 | AJ15: =COUNTIFS('Raw Data'!$C$2:$C$5000,$AJ$4, 'Raw Data'!$B$2:$B$5000,AC15) -> 5 | AK15: =COUNTIFS('Raw Data'!$C$2:$C$5000,$AK$4, 'Raw Data'!$B$2:$B$5000,AC16) -> 0
AC16: Violence | AD16: =COUNTIFS('Raw Data'!$C$2:$C$5000,$AD$4, 'Raw Data'!$B$2:$B$5000,AC16) -> 0 | AE16: =COUNTIFS('Raw Data'!$C$2:$C$5000,$AE$4, 'Raw Data'!$B$2:$B$5000,AC16) -> 0 | AF16: =COUNTIFS('Raw Data'!$C$2:$C$5000,$AF$4, 'Raw Data'!$B$2:$B$5000,AC16) -> 0 | AG16: =COUNTIFS('Raw Data'!$C$2:$C$1000,$AG$4, 'Raw Data'!$B$2:$B$1000,AC16) -> 0 | AH16: =COUNTIFS('Raw Data'!$C$2:$C$5000,$AH$4, 'Raw Data'!$B$2:$B$5000,AC16) -> 0 | AI16: =COUNTIFS('Raw Data'!$C$2:$C$5000,$AI$4, 'Raw Data'!$B$2:$B$5000,AC16) -> 0 | AJ16: =COUNTIFS('Raw Data'!$C$2:$C$5000,$AJ$4, 'Raw Data'!$B$2:$B$5000,AC16) -> 0 | AK16: =COUNTIFS('Raw Data'!$C$2:$C$5000,$AK$4, 'Raw Data'!$B$2:$B$5000,AC17) -> 0
AC17: TOTAL | AD17: =SUM(AD6:AD16) -> 554 | AE17: =SUM(AE6:AE16) -> 421 | AF17: =SUM(AF6:AF16) -> 754 | AG17: =SUM(AG6:AG16) -> 27 | AH17: =SUM(AH6:AH16) -> 437 | AI17: =SUM(AI6:AI16) -> 227 | AJ17: =SUM(AJ6:AJ16) -> 278 | AK17: =SUM(AK6:AK16) -> 30

Sheet Sheet1
C4: City | D4: State | E4: Value
C5: Mumbai | D5: Maharashtra-(mum) | E5: 150
C6: Delhi | D6: Delhi | E6: 120
C7: Bangalore | D7: Karnataka | E7: 100
C8: Hyderabad | D8: Telangana | E8: 90
C9: Kolkata | D9: West Bengal | E9: 80
