Workbook
Name cameras: OFFSET(Analysis!$C$61, 0, 0, MAX(1, COUNTA(Analysis!$C$61:$C$81)), 1)
Name counts: OFFSET(Analysis!$D$61, 0, 0, MAX(1, COUNTA(Analysis!$C$61:$C$81)), 1)
Name COUNTVIO: OFFSET(Analysis!$D$3, 0, 0, MAX(1, COUNTA(Analysis!$D$3:$D$31)), 1)
Name DailyAvg: OFFSET(Analysis!$H$50, 0, 0, MAX(1, COUNTA(Analysis!$H$50:$H$55)), 1)
Name Evening: OFFSET(Analysis!$F$40, 0, 0, MAX(1, COUNTA(Analysis!$F$40:$F$45)), 1)
Name LessSevere: OFFSET(Analysis!$E$50, 0, 0, MAX(1, COUNTA(Analysis!$E$50:$E$55)), 1)
Name MoreSevere: OFFSET(Analysis!$F$50, 0, 0, MAX(1, COUNTA(Analysis!$F$50:$F$55)), 1)
Name Morning: OFFSET(Analysis!$E$40, 0, 0, MAX(1, COUNTA(Analysis!$E$40:$E$45)), 1)
Name Night: OFFSET(Analysis!$G$40, 0, 0, MAX(1, COUNTA(Analysis!$G$40:$G$45)), 1)
Name Rejected: OFFSET(Analysis!$G$61, 0, 0, MAX(1, COUNTA(Analysis!$G$61:$G$81)), 1)
Name Resolved: OFFSET(Analysis!$E$61, 0, 0, MAX(1, COUNTA(Analysis!$E$61:$E$81)), 1)
Name Unresolved: OFFSET(Analysis!$F$61, 0, 0, MAX(1, COUNTA(Analysis!$F$61:$F$81)), 1)
Name VIO: OFFSET(Analysis!$C$3, 0, 0, MAX(1, COUNTA(Analysis!$C$3:$C$31)), 1)
Name violations: OFFSET(Analysis!$P$3, 0, 0, MAX(1, COUNTA(Analysis!$P$3:$P$83)), 1)
Name week: OFFSET(Analysis!$D$40, 0, 0, MAX(1, COUNTA(Analysis!$D$40:$D$45)), 1)

Sheet Raw Data
A1: violation_timestamp | B1: violation_name | C1: Location | D1: Camera Name | E1: image_url | F1: Action Status | G1: Action Status-1 | H1: image | I1: Severity | J1: week_num | K1: Date | L1: Time | M1: Shift | N1: Buttons | O1: images
A2: 22-May-2025 09:16:13 | B2: Work At Height | C2: Guwahati | D2: International | E2: https://smile-ai-test.s3.ap-south-1.amazonaws.com/content/violation/wah/frame/74857_20250522T034612_wah_p.jpg | F2: 0 | G2: =IF(ISBLANK(A2), "", IF(ISBLANK(F2), 0, F2)) -> 0 | H2: =IF(ISBLANK(E2),"",HYPERLINK(E2,"Click here")) -> Click here | I2: =IFERROR(INDEX(Analysis!$D$116:$N$137, MATCH(B2, Analysis!$C$116:$C$137, 0), MATCH(C2, Analysis!$D$115:$N$115, 0)), "") -> Severe | J2: =IF(ISBLANK(A2),"",WEEKNUM(A2)) -> 21 | K2: =IF(ISBLANK(A2),"",DATE(YEAR(A2),MONTH(A2),DAY(A2))) -> 45799 | L2: =IF(A2="", "", A2 - INT(A2)) -> 0.38626157 | M2: {=IF(L2="","",_xlfn.IFS( AND(L2>=TIME(9,0,0), L2<TIME(16,0,0)),"Morning", AND(L2>=TIME(16,0,0), L2<TIME(23,59,0)),"Evening", L2>=TIME(23,59,0),"Night", L2<TIME(9,0,0),"Night" ))} -> Morning | N2: Off | O2: =IF(N2="ON", _xlfn.IMAGE(E2, 1), "")
A3: 22-May-2025 09:16:30 | B3: Work At Height | C3: Guwahati | D3: International | E3: https://smile-ai-test.s3.ap-south-1.amazonaws.com/content/violation/wah/frame/39277_20250522T034629_wah_p.jpg | F3: 0 | G3: =IF(ISBLANK(A3), "", IF(ISBLANK(F3), 0, F3)) -> 0 | H3: =IF(ISBLANK(E3),"",HYPERLINK(E3,"Click here")) -> Click here | I3: =IFERROR(INDEX(Analysis!$D$116:$N$137, MATCH(B3, Analysis!$C$116:$C$137, 0), MATCH(C3, Analysis!$D$115:$N$115, 0)), "") -> Severe | J3: =IF(ISBLANK(A3),"",WEEKNUM(A3)) -> 21 | K3: =IF(ISBLANK(A3),"",DATE(YEAR(A3),MONTH(A3),DAY(A3))) -> 45799 | L3: =IF(A3="", "", A3 - INT(A3)) -> 0.38645833 | M3: {=IF(L3="","",_xlfn.IFS( AND(L3>=TIME(9,0,0), L3<TIME(16,0,0)),"Morning", AND(L3>=TIME(16,0,0), L3<TIME(23,59,0)),"Evening", L3>=TIME(23,59,0),"Night", L3<TIME(9,0,0),"Night" ))} -> Morning | N3: Off | O3: =IF(N3="ON", _xlfn.IMAGE(E3, 1), "")
A4: 22-May-2025 09:19:23 | B4: PPE | C4: Guwahati | D4: City Side Overbridge 1 | E4: https://smile-ai-test.s3.ap-south-1.amazonaws.com/content/violation/ppe/frame/66843_20250522T034921_ppe_p.jpg | F4: 0 | G4: =IF(ISBLANK(A4), "", IF(ISBLANK(F4), 0, F4)) -> 0 | H4: =IF(ISBLANK(E4),"",HYPERLINK(E4,"Click here")) -> Click here | I4: =IFERROR(INDEX(Analysis!$D$116:$N$137, MATCH(B4, Analysis!$C$116:$C$137, 0), MATCH(C4, Analysis!$D$115:$N$115, 0)), "") -> Mild | J4: =IF(ISBLANK(A4),"",WEEKNUM(A4)) -> 21 | K4: =IF(ISBLANK(A4),"",DATE(YEAR(A4),MONTH(A4),DAY(A4))) -> 45799 | L4: =IF(A4="", "", A4 - INT(A4)) -> 0.38846065 | M4: {=IF(L4="","",_xlfn.IFS( AND(L4>=TIME(9,0,0), L4<TIME(16,0,0)),"Morning", AND(L4>=TIME(16,0,0), L4<TIME(23,59,0)),"Evening", L4>=TIME(23,59,0),"Night", L4<TIME(9,0,0),"Night" ))} -> Morning | N4: Off | O4: =IF(N4="ON", _xlfn.IMAGE(E4, 1), "")
A5: 22-May-2025 09:20:54 | B5: PPE | C5: Guwahati | D5: Front Office | E5: https://smile-ai-test.s3.ap-south-1.amazonaws.com/content/violation/ppe/frame/65601_20250522T035050_ppe_p.jpg | F5: 0 | G5: =IF(ISBLANK(A5), "", IF(ISBLANK(F5), 0, F5)) -> 0 | H5: =IF(ISBLANK(E5),"",HYPERLINK(E5,"Click here")) -> Click here | I5: =IFERROR(INDEX(Analysis!$D$116:$N$137, MATCH(B5, Analysis!$C$116:$C$137, 0), MATCH(C5, Analysis!$D$115:$N$115, 0)), "") -> Mild | J5: =IF(ISBLANK(A5),"",WEEKNUM(A5)) -> 21 | K5: =IF(ISBLANK(A5),"",DATE(YEAR(A5),MONTH(A5),DAY(A5))) -> 45799 | L5: =IF(A5="", "", A5 - INT(A5)) -> 0.38951389 | M5: {=IF(L5="","",_xlfn.IFS( AND(L5>=TIME(9,0,0), L5<TIME(16,0,0)),"Morning", AND(L5>=TIME(16,0,0), L5<TIME(23,59,0)),"Evening", L5>=TIME(23,59,0),"Night", L5<TIME(9,0,0),"Night" ))} -> Morning | O5: =IF(N5="ON", _xlfn.IMAGE(E5, 1), "")
A6: 22-May-2025 09:30:59 | B6: PPE | C6: Guwahati | D6: Front Office | E6: https://smile-ai-test.s3.ap-south-1.amazonaws.com/content/violation/ppe/frame/87181_20250522T040056_ppe_p.jpg | F6: 0 | G6: =IF(ISBLANK(A6), "", IF(ISBLANK(F6), 0, F6)) -> 0 | H6: =IF(ISBLANK(E6),"",HYPERLINK(E6,"Click here")) -> Click here | I6: =IFERROR(INDEX(Analysis!$D$116:$N$137, MATCH(B6, Analysis!$C$116:$C$137, 0), MATCH(C6, Analysis!$D$115:$N$115, 0)), "") -> Mild | J6: =IF(ISBLANK(A6),"",WEEKNUM(A6)) -> 21 | K6: =IF(ISBLANK(A6),"",DATE(YEAR(A6),MONTH(A6),DAY(A6))) -> 45799 | L6: =IF(A6="", "", A6 - INT(A6)) -> 0.3965162 | M6: {=IF(L6="","",_xlfn.IFS( AND(L6>=TIME(9,0,0), L6<TIME(16,0,0)),"Morning", AND(L6>=TIME(16,0,0), L6<TIME(23,59,0)),"Evening", L6>=TIME(23,59,0),"Night", L6<TIME(9,0,0),"Night" ))} -> Morning | O6: =IF(N6="ON", _xlfn.IMAGE(E6, 1), "")
A7: 22-May-2025 09:40:11 | B7: PPE | C7: Guwahati | D7: City Side Overbridge 1 | E7: https://smile-ai-test.s3.ap-south-1.amazonaws.com/content/violation/ppe/frame/28508_20250522T041009_ppe_p.jpg | F7: 0 | G7: =IF(ISBLANK(A7), "", IF(ISBLANK(F7), 0, F7)) -> 0 | H7: =IF(ISBLANK(E7),"",HYPERLINK(E7,"Click here")) -> Click here | I7: =IFERROR(INDEX(Analysis!$D$116:$N$137, MATCH(B7, Analysis!$C$116:$C$137, 0), MATCH(C7, Analysis!$D$115:$N$115, 0)), "") -> Mild | J7: =IF(ISBLANK(A7),"",WEEKNUM(A7)) -> 21 | K7: =IF(ISBLANK(A7),"",DATE(YEAR(A7),MONTH(A7),DAY(A7))) -> 45799 | L7: =IF(A7="", "", A7 - INT(A7)) -> 0.40290509 | M7: {=IF(L7="","",_xlfn.IFS( AND(L7>=TIME(9,0,0), L7<TIME(16,0,0)),"Morning", AND(L7>=TIME(16,0,0), L7<TIME(23,59,0)),"Evening", L7>=TIME(23,59,0),"Night", L7<TIME(9,0,0),"Night" ))} -> Morning | O7: =IF(N7="ON", _xlfn.IMAGE(E7, 1), "") | Q7: {=IF(P7="","",_xlfn.IFS( AND(P7>=TIME(9,0,0), P7<TIME(16,0,0)),"Morning", AND(P7>=TIME(16,0,0), P7<TIME(23,59,0)),"Evening", P7>=TIME(23,59,0),"Night", P7<TIME(9,0,0),"Night" ))}
A8: 22-May-2025 09:41:05 | B8: PPE | C8: Guwahati | D8: Front Office | E8: https://smile-ai-test.s3.ap-south-1.amazonaws.com/content/violation/ppe/frame/66132_20250522T041102_ppe_p.jpg | F8: 0 | G8: =IF(ISBLANK(A8), "", IF(ISBLANK(F8), 0, F8)) -> 0 | H8: =IF(ISBLANK(E8),"",HYPERLINK(E8,"Click here")) -> Click here | I8: =IFERROR(INDEX(Analysis!$D$116:$N$137, MATCH(B8, Analysis!$C$116:$C$137, 0), MATCH(C8, Analysis!$D$115:$N$115, 0)), "") -> Mild | J8: =IF(ISBLANK(A8),"",WEEKNUM(A8)) -> 21 | K8: =IF(ISBLANK(A8),"",DATE(YEAR(A8),MONTH(A8),DAY(A8))) -> 45799 | L8: =IF(A8="", "", A8 - INT(A8)) -> 0.40353009 | M8: {=IF(L8="","",_xlfn.IFS( AND(L8>=TIME(9,0,0), L8<TIME(16,0,0)),"Morning", AND(L8>=TIME(16,0,0), L8<TIME(23,59,0)),"Evening", L8>=TIME(23,59,0),"Night", L8<TIME(9,0,0),"Night" ))} -> Morning | O8: =IF(N8="ON", _xlfn.IMAGE(E8, 1), "")
A9: 22-May-2025 09:56:33 | B9: PPE | C9: Guwahati | D9: AirSide | E9: https://smile-ai-test.s3.ap-south-1.amazonaws.com/content/violation/ppe/frame/90296_20250522T042630_ppe_p.jpg | F9: 0 | G9: =IF(ISBLANK(A9), "", IF(ISBLANK(F9), 0, F9)) -> 0 | H9: =IF(ISBLANK(E9),"",HYPERLINK(E9,"Click here")) -> Click here | I9: =IFERROR(INDEX(Analysis!$D$116:$N$137, MATCH(B9, Analysis!$C$116:$C$137, 0), MATCH(C9, Analysis!$D$115:$N$115, 0)), "") -> Mild | J9: =IF(ISBLANK(A9),"",WEEKNUM(A9)) -> 21 | K9: =IF(ISBLANK(A9),"",DATE(YEAR(A9),MONTH(A9),DAY(A9))) -> 45799 | L9: =IF(A9="", "", A9 - INT(A9)) -> 0.41427083 | M9: {=IF(L9="","",_xlfn.IFS( AND(L9>=TIME(9,0,0), L9<TIME(16,0,0)),"Morning", AND(L9>=TIME(16,0,0), L9<TIME(23,59,0)),"Evening", L9>=TIME(23,59,0),"Night", L9<TIME(9,0,0),"Night" ))} -> Morning | O9: =IF(N9="ON", _xlfn.IMAGE(E9, 1), "")
A10: 22-May-2025 10:13:02 | B10: Welding / Gas cutting | C10: Guwahati | D10: City Side Overbridge 1 | E10: https://smile-ai-test.s3.ap-south-1.amazonaws.com/content/violation/fire/frame/88693_20250522T044300_fire_p.jpg | F10: 0 | G10: =IF(ISBLANK(A10), "", IF(ISBLANK(F10), 0, F10)) -> 0 | H10: =IF(ISBLANK(E10),"",HYPERLINK(E10,"Click here")) -> Click here | I10: =IFERROR(INDEX(Analysis!$D$116:$N$137, MATCH(B10, Analysis!$C$116:$C$137, 0), MATCH(C10, Analysis!$D$115:$N$115, 0)), "") -> Mild | J10: =IF(ISBLANK(A10),"",WEEKNUM(A10)) -> 21 | K10: =IF(ISBLANK(A10),"",DATE(YEAR(A10),MONTH(A10),DAY(A10))) -> 45799 | L10: =IF(A10="", "", A10 - INT(A10)) -> 0.42571759 | M10: {=IF(L10="","",_xlfn.IFS( AND(L10>=TIME(9,0,0), L10<TIME(16,0,0)),"Morning", AND(L10>=TIME(16,0,0), L10<TIME(23,59,0)),"Evening", L10>=TIME(23,59,0),"Night", L10<TIME(9,0,0),"Night" ))} -> Morning | N10: Off | O10: =IF(N10="ON", _xlfn.IMAGE(E10, 1), "")
A11: 22-May-2025 10:20:56 | B11: PPE | C11: Guwahati | D11: Front Office | E11: https://smile-ai-test.s3.ap-south-1.amazonaws.com/content/violation/ppe/frame/12955_20250522T045053_ppe_p.jpg | F11: 0 | G11: =IF(ISBLANK(A11), "", IF(ISBLANK(F11), 0, F11)) -> 0 | H11: =IF(ISBLANK(E11),"",HYPERLINK(E11,"Click here")) -> Click here | I11: =IFERROR(INDEX(Analysis!$D$116:$N$137, MATCH(B11, Analysis!$C$116:$C$137, 0), MATCH(C11, Analysis!$D$115:$N$115, 0)), "") -> Mild | J11: =IF(ISBLANK(A11),"",WEEKNUM(A11)) -> 21 | K11: =IF(ISBLANK(A11),"",DATE(YEAR(A11),MONTH(A11),DAY(A11))) -> 45799 | L11: =IF(A11="", "", A11 - INT(A11)) -> 0.4312037 | M11: {=IF(L11="","",_xlfn.IFS( AND(L11>=TIME(9,0,0), L11<TIME(16,0,0)),"Morning", AND(L11>=TIME(16,0,0), L11<TIME(23,59,0)),"Evening", L11>=TIME(23,59,0),"Night", L11<TIME(9,0,0),"Night" ))} -> Morning | O11: =IF(N11="ON", _xlfn.IMAGE(E11, 1), "")
A12: 22-May-2025 10:21:09 | B12: PPE | C12: Guwahati | D12: Front Office | E12: https://smile-ai-test.s3.ap-south-1.amazonaws.com/content/violation/ppe/frame/41480_20250522T045106_ppe_p.jpg | F12: 0 | G12: =IF(ISBLANK(A12), "", IF(ISBLANK(F12), 0, F12)) -> 0 | H12: =IF(ISBLANK(E12),"",HYPERLINK(E12,"Click here")) -> Click here | I12: =IFERROR(INDEX(Analysis!$D$116:$N$137, MATCH(B12, Analysis!$C$116:$C$137, 0), MATCH(C12, Analysis!$D$115:$N$115, 0)), "") -> Mild | J12: =IF(ISBLANK(A12),"",WEEKNUM(A12)) -> 21 | K12: =IF(ISBLANK(A12),"",DATE(YEAR(A12),MONTH(A12),DAY(A12))) -> 45799 | L12: =IF(A12="", "", A12 - INT(A12)) -> 0.43135417 | M12: {=IF(L12="","",_xlfn.IFS( AND(L12>=TIME(9,0,0), L12<TIME(16,0,0)),"Morning", AND(L12>=TIME(16,0,0), L12<TIME(23,59,0)),"Evening", L12>=TIME(23,59,0),"Night", L12<TIME(9,0,0),"Night" ))} -> Morning | O12: =IF(N12="ON", _xlfn.IMAGE(E12, 1), "")
A13: 22-May-2025 12:40:51 | B13: Vehicle Reverse Flagman | C13: Guwahati | D13: Departure, Zone 5 | E13: https://smile-ai-test.s3.ap-south-1.amazonaws.com/content/violation/flagman/frame/63722_20250522T071048_flagman_p.jpg | F13: 0 | G13: =IF(ISBLANK(A13), "", IF(ISBLANK(F13), 0, F13)) -> 0 | H13: =IF(ISBLANK(E13),"",HYPERLINK(E13,"Click here")) -> Click here | I13: =IFERROR(INDEX(Analysis!$D$116:$N$137, MATCH(B13, Analysis!$C$116:$C$137, 0), MATCH(C13, Analysis!$D$115:$N$115, 0)), "") -> Severe | J13: =IF(ISBLANK(A13),"",WEEKNUM(A13)) -> 21 | K13: =IF(ISBLANK(A13),"",DATE(YEAR(A13),MONTH(A13),DAY(A13))) -> 45799 | L13: =IF(A13="", "", A13 - INT(A13)) -> 0.52836806 | M13: {=IF(L13="","",_xlfn.IFS( AND(L13>=TIME(9,0,0), L13<TIME(16,0,0)),"Morning", AND(L13>=TIME(16,0,0), L13<TIME(23,59,0)),"Evening", L13>=TIME(23,59,0),"Night", L13<TIME(9,0,0),"Night" ))} -> Morning | O13: =IF(N13="ON", _xlfn.IMAGE(E13, 1), "")
A14: 22-May-2025 12:46:25 | B14: PPE | C14: Guwahati | D14: City Side Overbridge 2 | E14: https://smile-ai-test.s3.ap-south-1.amazonaws.com/content/violation/ppe/frame/18843_20250522T071622_ppe_p.jpg | F14: 0 | G14: =IF(ISBLANK(A14), "", IF(ISBLANK(F14), 0, F14)) -> 0 | H14: =IF(ISBLANK(E14),"",HYPERLINK(E14,"Click here")) -> Click here | I14: =IFERROR(INDEX(Analysis!$D$116:$N$137, MATCH(B14, Analysis!$C$116:$C$137, 0), MATCH(C14, Analysis!$D$115:$N$115, 0)), "") -> Mild | J14: =IF(ISBLANK(A14),"",WEEKNUM(A14)) -> 21 | K14: =IF(ISBLANK(A14),"",DATE(YEAR(A14),MONTH(A14),DAY(A14))) -> 45799 | L14: =IF(A14="", "", A14 - INT(A14)) -> 0.5322338 | M14: {=IF(L14="","",_xlfn.IFS( AND(L14>=TIME(9,0,0), L14<TIME(16,0,0)),"Morning", AND(L14>=TIME(16,0,0), L14<TIME(23,59,0)),"Evening", L14>=TIME(23,59,0),"Night", L14<TIME(9,0,0),"Night" ))} -> Morning | O14: =IF(N14="ON", _xlfn.IMAGE(E14, 1), "")
A15: 22-May-2025 13:59:12 | B15: Unconscious/Resting | C15: Guwahati | D15: City Side Overbridge 1 | E15: https://smile-ai-test.s3.ap-south-1.amazonaws.com/content/violation/fall/frame/34440_20250522T082910_fall_p.jpg | F15: 0 | G15: =IF(ISBLANK(A15), "", IF(ISBLANK(F15), 0, F15)) -> 0 | H15: =IF(ISBLANK(E15),"",HYPERLINK(E15,"Click here")) -> Click here | I15: =IFERROR(INDEX(Analysis!$D$116:$N$137, MATCH(B15, Analysis!$C$116:$C$137, 0), MATCH(C15, Analysis!$D$115:$N$115, 0)), "") -> Severe | J15: =IF(ISBLANK(A15),"",WEEKNUM(A15)) -> 21 | K15: =IF(ISBLANK(A15),"",DATE(YEAR(A15),MONTH(A15),DAY(A15))) -> 45799 | L15: =IF(A15="", "", A15 - INT(A15)) -> 0.58277778 | M15: {=IF(L15="","",_xlfn.IFS( AND(L15>=TIME(9,0,0), L15<TIME(16,0,0)),"Morning", AND(L15>=TIME(16,0,0), L15<TIME(23,59,0)),"Evening", L15>=TIME(23,59,0),"Night", L15<TIME(9,0,0),"Night" ))} -> Morning | O15: =IF(N15="ON", _xlfn.IMAGE(E15, 1), "")
A16: 22-May-2025 14:07:22 | B16: Vehicle Reverse Flagman | C16: Guwahati | D16: Departure, Zone 5 | E16: https://smile-ai-test.s3.ap-south-1.amazonaws.com/content/violation/flagman/frame/23444_20250522T083719_flagman_p.jpg | F16: 0 | G16: =IF(ISBLANK(A16), "", IF(ISBLANK(F16), 0, F16)) -> 0 | H16: =IF(ISBLANK(E16),"",HYPERLINK(E16,"Click here")) -> Click here | I16: =IFERROR(INDEX(Analysis!$D$116:$N$137, MATCH(B16, Analysis!$C$116:$C$137, 0), MATCH(C16, Analysis!$D$115:$N$115, 0)), "") -> Severe | J16: =IF(ISBLANK(A16),"",WEEKNUM(A16)) -> 21 | K16: =IF(ISBLANK(A16),"",DATE(YEAR(A16),MONTH(A16),DAY(A16))) -> 45799 | L16: =IF(A16="", "", A16 - INT(A16)) -> 0.58844907 | M16: {=IF(L16="","",_xlfn.IFS( AND(L16>=TIME(9,0,0), L16<TIME(16,0,0)),"Morning", AND(L16>=TIME(16,0,0), L16<TIME(23,59,0)),"Evening", L16>=TIME(23,59,0),"Night", L16<TIME(9,0,0),"Night" ))} -> Morning | O16: =IF(N16="ON", _xlfn.IMAGE(E16, 1), "")
A17: 22-May-2025 14:08:02 | B17: PPE | C17: Guwahati | D17: City Side Overbridge 1 | E17: https://smile-ai-test.s3.ap-south-1.amazonaws.com/content/violation/ppe/frame/36242_20250522T083800_ppe_p.jpg | F17: 0 | G17: =IF(ISBLANK(A17), "", IF(ISBLANK(F17), 0, F17)) -> 0 | H17: =IF(ISBLANK(E17),"",HYPERLINK(E17,"Click here")) -> Click here | I17: =IFERROR(INDEX(Analysis!$D$116:$N$137, MATCH(B17, Analysis!$C$116:$C$137, 0), MATCH(C17, Analysis!$D$115:$N$115, 0)), "") -> Mild | J17: =IF(ISBLANK(A17),"",WEEKNUM(A17)) -> 21 | K17: =IF(ISBLANK(A17),"",DATE(YEAR(A17),MONTH(A17),DAY(A17))) -> 45799 | L17: =IF(A17="", "", A17 - INT(A17)) -> 0.58891204 | M17: {=IF(L17="","",_xlfn.IFS( AND(L17>=TIME(9,0,0), L17<TIME(16,0,0)),"Morning", AND(L17>=TIME(16,0,0), L17<TIME(23,59,0)),"Evening", L17>=TIME(23,59,0),"Night", L17<TIME(9,0,0),"Night" ))} -> Morning | O17: =IF(N17="ON", _xlfn.IMAGE(E17, 1), "")
A18: 22-May-2025 14:08:19 | B18: PPE | C18: Guwahati | D18: City Side Overbridge 1 | E18: https://smile-ai-test.s3.ap-south-1.amazonaws.com/content/violation/ppe/frame/42401_20250522T083817_ppe_p.jpg | F18: 0 | G18: =IF(ISBLANK(A18), "", IF(ISBLANK(F18), 0, F18)) -> 0 | H18: =IF(ISBLANK(E18),"",HYPERLINK(E18,"Click here")) -> Click here | I18: =IFERROR(INDEX(Analysis!$D$116:$N$137, MATCH(B18, Analysis!$C$116:$C$137, 0), MATCH(C18, Analysis!$D$115:$N$115, 0)), "") -> Mild | J18: =IF(ISBLANK(A18),"",WEEKNUM(A18)) -> 21 | K18: =IF(ISBLANK(A18),"",DATE(YEAR(A18),MONTH(A18),DAY(A18))) -> 45799 | L18: =IF(A18="", "", A18 - INT(A18)) -> 0.5891088 | M18: {=IF(L18="","",_xlfn.IFS( AND(L18>=TIME(9,0,0), L18<TIME(16,0,0)),"Morning", AND(L18>=TIME(16,0,0), L18<TIME(23,59,0)),"Evening", L18>=TIME(23,59,0),"Night", L18<TIME(9,0,0),"Night" ))} -> Morning | O18: =IF(N18="ON", _xlfn.IMAGE(E18, 1), "")
A19: 22-May-2025 14:09:08 | B19: Unconscious/Resting | C19: Guwahati | D19: City Side Overbridge 2 | E19: https://smile-ai-test.s3.ap-south-1.amazonaws.com/content/violation/fall/frame/97580_20250522T083905_fall_p.jpg | F19: 0 | G19: =IF(ISBLANK(A19), "", IF(ISBLANK(F19), 0, F19)) -> 0 | H19: =IF(ISBLANK(E19),"",HYPERLINK(E19,"Click here")) -> Click here | I19: =IFERROR(INDEX(Analysis!$D$116:$N$137, MATCH(B19, Analysis!$C$116:$C$137, 0), MATCH(C19, Analysis!$D$115:$N$115, 0)), "") -> Severe | J19: =IF(ISBLANK(A19),"",WEEKNUM(A19)) -> 21 | K19: =IF(ISBLANK(A19),"",DATE(YEAR(A19),MONTH(A19),DAY(A19))) -> 45799 | L19: =IF(A19="", "", A19 - INT(A19)) -> 0.58967593 | M19: {=IF(L19="","",_xlfn.IFS( AND(L19>=TIME(9,0,0), L19<TIME(16,0,0)),"Morning", AND(L19>=TIME(16,0,0), L19<TIME(23,59,0)),"Evening", L19>=TIME(23,59,0),"Night", L19<TIME(9,0,0),"Night" ))} -> Morning | O19: =IF(N19="ON", _xlfn.IMAGE(E19, 1), "")
A20: 22-May-2025 14:21:05 | B20: PPE | C20: Guwahati | D20: AirSide | E20: https://smile-ai-test.s3.ap-south-1.amazonaws.com/content/violation/ppe/frame/64945_20250522T085103_ppe_p.jpg | F20: 0 | G20: =IF(ISBLANK(A20), "", IF(ISBLANK(F20), 0, F20)) -> 0 | H20: =IF(ISBLANK(E20),"",HYPERLINK(E20,"Click here")) -> Click here | I20: =IFERROR(INDEX(Analysis!$D$116:$N$137, MATCH(B20, Analysis!$C$116:$C$137, 0), MATCH(C20, Analysis!$D$115:$N$115, 0)), "") -> Mild | J20: =IF(ISBLANK(A20),"",WEEKNUM(A20)) -> 21 | K20: =IF(ISBLANK(A20),"",DATE(YEAR(A20),MONTH(A20),DAY(A20))) -> 45799 | L20: =IF(A20="", "", A20 - INT(A20)) -> 0.59797454 | M20: {=IF(L20="","",_xlfn.IFS( AND(L20>=TIME(9,0,0), L20<TIME(16,0,0)),"Morning", AND(L20>=TIME(16,0,0), L20<TIME(23,59,0)),"Evening", L20>=TIME(23,59,0),"Night", L20<TIME(9,0,0),"Night" ))} -> Morning | N20: Off | O20: =IF(N20="ON", _xlfn.IMAGE(E20, 1), "")
A21: 22-May-2025 14:41:49 | B21: Vehicle Reverse Flagman | C21: Guwahati | D21: Front Office | E21: https://smile-ai-test.s3.ap-south-1.amazonaws.com/content/violation/flagman/frame/57320_20250522T091146_flagman_p.jpg | F21: 0 | G21: =IF(ISBLANK(A21), "", IF(ISBLANK(F21), 0, F21)) -> 0 | H21: =IF(ISBLANK(E21),"",HYPERLINK(E21,"Click here")) -> Click here | I21: =IFERROR(INDEX(Analysis!$D$116:$N$137, MATCH(B21, Analysis!$C$116:$C$137, 0), MATCH(C21, Analysis!$D$115:$N$115, 0)), "") -> Severe | J21: =IF(ISBLANK(A21),"",WEEKNUM(A21)) -> 21 | K21: =IF(ISBLANK(A21),"",DATE(YEAR(A21),MONTH(A21),DAY(A21))) -> 45799 | L21: =IF(A21="", "", A21 - INT(A21)) -> 0.61237269 | M21: {=IF(L21="","",_xlfn.IFS( AND(L21>=TIME(9,0,0), L21<TIME(16,0,0)),"Morning", AND(L21>=TIME(16,0,0), L21<TIME(23,59,0)),"Evening", L21>=TIME(23,59,0),"Night", L21<TIME(9,0,0),"Night" ))} -> Morning | O21: =IF(N21="ON", _xlfn.IMAGE(E21, 1), "")
A22: 22-May-2025 14:48:48 | B22: Welding / Gas cutting | C22: Guwahati | D22: City Side Overbridge 1 | E22: https://smile-ai-test.s3.ap-south-1.amazonaws.com/content/violation/fire/frame/92930_20250522T091847_fire_p.jpg | F22: 0 | G22: =IF(ISBLANK(A22), "", IF(ISBLANK(F22), 0, F22)) -> 0 | H22: =IF(ISBLANK(E22),"",HYPERLINK(E22,"Click here")) -> Click here | I22: =IFERROR(INDEX(Analysis!$D$116:$N$137, MATCH(B22, Analysis!$C$116:$C$137, 0), MATCH(C22, Analysis!$D$115:$N$115, 0)), "") -> Mild | J22: =IF(ISBLANK(A22),"",WEEKNUM(A22)) -> 21 | K22: =IF(ISBLANK(A22),"",DATE(YEAR(A22),MONTH(A22),DAY(A22))) -> 45799 | L22: =IF(A22="", "", A22 - INT(A22)) -> 0.61722222 | M22: {=IF(L22="","",_xlfn.IFS( AND(L22>=TIME(9,0,0), L22<TIME(16,0,0)),"Morning", AND(L22>=TIME(16,0,0), L22<TIME(23,59,0)),"Evening", L22>=TIME(23,59,0),"Night", L22<TIME(9,0,0),"Night" ))} -> Morning | O22: =IF(N22="ON", _xlfn.IMAGE(E22, 1), "")
A23: 22-May-2025 15:19:01 | B23: PPE | C23: Guwahati | D23: City Side HM | E23: https://smile-ai-test.s3.ap-south-1.amazonaws.com/content/violation/ppe/frame/59574_20250522T094859_ppe_p.jpg | F23: 0 | G23: =IF(ISBLANK(A23), "", IF(ISBLANK(F23), 0, F23)) -> 0 | H23: =IF(ISBLANK(E23),"",HYPERLINK(E23,"Click here")) -> Click here | I23: =IFERROR(INDEX(Analysis!$D$116:$N$137, MATCH(B23, Analysis!$C$116:$C$137, 0), MATCH(C23, Analysis!$D$115:$N$115, 0)), "") -> Mild | J23: =IF(ISBLANK(A23),"",WEEKNUM(A23)) -> 21 | K23: =IF(ISBLANK(A23),"",DATE(YEAR(A23),MONTH(A23),DAY(A23))) -> 45799 | L23: =IF(A23="", "", A23 - INT(A23)) -> 0.63820602 | M23: {=IF(L23="","",_xlfn.IFS( AND(L23>=TIME(9,0,0), L23<TIME(16,0,0)),"Morning", AND(L23>=TIME(16,0,0), L23<TIME(23,59,0)),"Evening", L23>=TIME(23,59,0),"Night", L23<TIME(9,0,0),"Night" ))} -> Morning | O23: =IF(N23="ON", _xlfn.IMAGE(E23, 1), "")
A24: 22-May-2025 15:19:18 | B24: PPE | C24: Guwahati | D24: City Side HM | E24: https://smile-ai-test.s3.ap-south-1.amazonaws.com/content/violation/ppe/frame/88871_20250522T094917_ppe_p.jpg | F24: 0 | G24: =IF(ISBLANK(A24), "", IF(ISBLANK(F24), 0, F24)) -> 0 | H24: =IF(ISBLANK(E24),"",HYPERLINK(E24,"Click here")) -> Click here | I24: =IFERROR(INDEX(Analysis!$D$116:$N$137, MATCH(B24, Analysis!$C$116:$C$137, 0), MATCH(C24, Analysis!$D$115:$N$115, 0)), "") -> Mild | J24: =IF(ISBLANK(A24),"",WEEKNUM(A24)) -> 21 | K24: =IF(ISBLANK(A24),"",DATE(YEAR(A24),MONTH(A24),DAY(A24))) -> 45799 | L24: =IF(A24="", "", A24 - INT(A24)) -> 0.63840278 | M24: {=IF(L24="","",_xlfn.IFS( AND(L24>=TIME(9,0,0), L24<TIME(16,0,0)),"Morning", AND(L24>=TIME(16,0,0), L24<TIME(23,59,0)),"Evening", L24>=TIME(23,59,0),"Night", L24<TIME(9,0,0),"Night" ))} -> Morning | O24: =IF(N24="ON", _xlfn.IMAGE(E24, 1), "")
A25: 22-May-2025 15:22:23 | B25: Vehicle Reverse Flagman | C25: Guwahati | D25: International | E25: https://smile-ai-test.s3.ap-south-1.amazonaws.com/content/violation/flagman/frame/13244_20250522T095221_flagman_p.jpg | F25: 0 | G25: =IF(ISBLANK(A25), "", IF(ISBLANK(F25), 0, F25)) -> 0 | H25: =IF(ISBLANK(E25),"",HYPERLINK(E25,"Click here")) -> Click here | I25: =IFERROR(INDEX(Analysis!$D$116:$N$137, MATCH(B25, Analysis!$C$116:$C$137, 0), MATCH(C25, Analysis!$D$115:$N$115, 0)), "") -> Severe | J25: =IF(ISBLANK(A25),"",WEEKNUM(A25)) -> 21 | K25: =IF(ISBLANK(A25),"",DATE(YEAR(A25),MONTH(A25),DAY(A25))) -> 45799 | L25: =IF(A25="", "", A25 - INT(A25)) -> 0.64054398 | M25: {=IF(L25="","",_xlfn.IFS( AND(L25>=TIME(9,0,0), L25<TIME(16,0,0)),"Morning", AND(L25>=TIME(16,0,0), L25<TIME(23,59,0)),"Evening", L25>=TIME(23,59,0),"Night", L25<TIME(9,0,0),"Night" ))} -> Morning | O25: =IF(N25="ON", _xlfn.IMAGE(E25, 1), "")
A26: 22-May-2025 15:56:17 | B26: Unauthorized Access | C26: Guwahati | D26: Front Office | E26: https://smile-ai-test.s3.ap-south-1.amazonaws.com/content/violation/unsafe/frame/59390_20250522T102614_unsafe_p.jpg | F26: 0 | G26: =IF(ISBLANK(A26), "", IF(ISBLANK(F26), 0, F26)) -> 0 | H26: =IF(ISBLANK(E26),"",HYPERLINK(E26,"Click here")) -> Click here | I26: =IFERROR(INDEX(Analysis!$D$116:$N$137, MATCH(B26, Analysis!$C$116:$C$137, 0), MATCH(C26, Analysis!$D$115:$N$115, 0)), "") -> Severe | J26: =IF(ISBLANK(A26),"",WEEKNUM(A26)) -> 21 | K26: =IF(ISBLANK(A26),"",DATE(YEAR(A26),MONTH(A26),DAY(A26))) -> 45799 | L26: =IF(A26="", "", A26 - INT(A26)) -> 0.66408565 | M26: {=IF(L26="","",_xlfn.IFS( AND(L26>=TIME(9,0,0), L26<TIME(16,0,0)),"Morning", AND(L26>=TIME(16,0,0), L26<TIME(23,59,0)),"Evening", L26>=TIME(23,59,0),"Night", L26<TIME(9,0,0),"Night" ))} -> Morning | O26: =IF(N26="ON", _xlfn.IMAGE(E26, 1), "")
A27: 22-May-2025 16:20:02 | B27: Welding / Gas cutting | C27: Guwahati | D27: City Side Overbridge 1 | E27: https://smile-ai-test.s3.ap-south-1.amazonaws.com/content/violation/fire/frame/59776_20250522T105000_fire_p.jpg | F27: 0 | G27: =IF(ISBLANK(A27), "", IF(ISBLANK(F27), 0, F27)) -> 0 | H27: =IF(ISBLANK(E27),"",HYPERLINK(E27,"Click here")) -> Click here | I27: =IFERROR(INDEX(Analysis!$D$116:$N$137, MATCH(B27, Analysis!$C$116:$C$137, 0), MATCH(C27, Analysis!$D$115:$N$115, 0)), "") -> Mild | J27: =IF(ISBLANK(A27),"",WEEKNUM(A27)) -> 21 | K27: =IF(ISBLANK(A27),"",DATE(YEAR(A27),MONTH(A27),DAY(A27))) -> 45799 | L27: =IF(A27="", "", A27 - INT(A27)) -> 0.6805787 | M27: {=IF(L27="","",_xlfn.IFS( AND(L27>=TIME(9,0,0), L27<TIME(16,0,0)),"Morning", AND(L27>=TIME(16,0,0), L27<TIME(23,59,0)),"Evening", L27>=TIME(23,59,0),"Night", L27<TIME(9,0,0),"Night" ))} -> Evening | O27: =IF(N27="ON", _xlfn.IMAGE(E27, 1), "")
A28: 22-May-2025 20:51:01 | B28: PPE | C28: Guwahati | D28: City Side HM | E28: https://smile-ai-test.s3.ap-south-1.amazonaws.com/content/violation/ppe/frame/76805_20250522T152100_ppe_p.jpg | F28: 0 | G28: =IF(ISBLANK(A28), "", IF(ISBLANK(F28), 0, F28)) -> 0 | H28: =IF(ISBLANK(E28),"",HYPERLINK(E28,"Click here")) -> Click here | I28: =IFERROR(INDEX(Analysis!$D$116:$N$137, MATCH(B28, Analysis!$C$116:$C$137, 0), MATCH(C28, Analysis!$D$115:$N$115, 0)), "") -> Mild | J28: =IF(ISBLANK(A28),"",WEEKNUM(A28)) -> 21 | K28: =IF(ISBLANK(A28),"",DATE(YEAR(A28),MONTH(A28),DAY(A28))) -> 45799 | L28: =IF(A28="", "", A28 - INT(A28)) -> 0.86876157 | M28: {=IF(L28="","",_xlfn.IFS( AND(L28>=TIME(9,0,0), L28<TIME(16,0,0)),"Morning", AND(L28>=TIME(16,0,0), L28<TIME(23,59,0)),"Evening", L28>=TIME(23,59,0),"Night", L28<TIME(9,0,0),"Night" ))} -> Evening | O28: =IF(N28="ON", _xlfn.IMAGE(E28, 1), "")
A29: 22-May-2025 20:51:22 | B29: PPE | C29: Guwahati | D29: City Side HM | E29: https://smile-ai-test.s3.ap-south-1.amazonaws.com/content/violation/ppe/frame/99642_20250522T152121_ppe_p.jpg | F29: 0 | G29: =IF(ISBLANK(A29), "", IF(ISBLANK(F29), 0, F29)) -> 0 | H29: =IF(ISBLANK(E29),"",HYPERLINK(E29,"Click here")) -> Click here | I29: =IFERROR(INDEX(Analysis!$D$116:$N$137, MATCH(B29, Analysis!$C$116:$C$137, 0), MATCH(C29, Analysis!$D$115:$N$115, 0)), "") -> Mild | J29: =IF(ISBLANK(A29),"",WEEKNUM(A29)) -> 21 | K29: =IF(ISBLANK(A29),"",DATE(YEAR(A29),MONTH(A29),DAY(A29))) -> 45799 | L29: =IF(A29="", "", A29 - INT(A29)) -> 0.86900463 | M29: {=IF(L29="","",_xlfn.IFS( AND(L29>=TIME(9,0,0), L29<TIME(16,0,0)),"Morning", AND(L29>=TIME(16,0,0), L29<TIME(23,59,0)),"Evening", L29>=TIME(23,59,0),"Night", L29<TIME(9,0,0),"Night" ))} -> Evening | O29: =IF(N29="ON", _xlfn.IMAGE(E29, 1), "")
A30: 22-May-2025 23:12:06 | B30: PPE | C30: Guwahati | D30: Front Office | E30: https://smile-ai-test.s3.ap-south-1.amazonaws.com/content/violation/ppe/frame/92982_20250522T174205_ppe_p.jpg | F30: 0 | G30: =IF(ISBLANK(A30), "", IF(ISBLANK(F30), 0, F30)) -> 0 | H30: =IF(ISBLANK(E30),"",HYPERLINK(E30,"Click here")) -> Click here | I30: =IFERROR(INDEX(Analysis!$D$116:$N$137, MATCH(B30, Analysis!$C$116:$C$137, 0), MATCH(C30, Analysis!$D$115:$N$115, 0)), "") -> Mild | J30: =IF(ISBLANK(A30),"",WEEKNUM(A30)) -> 21 | K30: =IF(ISBLANK(A30),"",DATE(YEAR(A30),MONTH(A30),DAY(A30))) -> 45799 | L30: =IF(A30="", "", A30 - INT(A30)) -> 0.96673611 | M30: {=IF(L30="","",_xlfn.IFS( AND(L30>=TIME(9,0,0), L30<TIME(16,0,0)),"Morning", AND(L30>=TIME(16,0,0), L30<TIME(23,59,0)),"Evening", L30>=TIME(23,59,0),"Night", L30<TIME(9,0,0),"Night" ))} -> Evening | O30: =IF(N30="ON", _xlfn.IMAGE(E30, 1), "")
A31: 23-May-2025 09:19:09 | B31: PPE | C31: Guwahati | D31: City Side Overbridge 2 | E31: https://smile-ai-test.s3.ap-south-1.amazonaws.com/content/violation/ppe/frame/58782_20250523T034906_ppe_p.jpg | F31: 0 | G31: =IF(ISBLANK(A31), "", IF(ISBLANK(F31), 0, F31)) -> 0 | H31: =IF(ISBLANK(E31),"",HYPERLINK(E31,"Click here")) -> Click here | I31: =IFERROR(INDEX(Analysis!$D$116:$N$137, MATCH(B31, Analysis!$C$116:$C$137, 0), MATCH(C31, Analysis!$D$115:$N$115, 0)), "") -> Mild | J31: =IF(ISBLANK(A31),"",WEEKNUM(A31)) -> 21 | K31: =IF(ISBLANK(A31),"",DATE(YEAR(A31),MONTH(A31),DAY(A31))) -> 45800 | L31: =IF(A31="", "", A31 - INT(A31)) -> 0.38829861 | M31: {=IF(L31="","",_xlfn.IFS( AND(L31>=TIME(9,0,0), L31<TIME(16,0,0)),"Morning", AND(L31>=TIME(16,0,0), L31<TIME(23,59,0)),"Evening", L31>=TIME(23,59,0),"Night", L31<TIME(9,0,0),"Night" ))} -> Morning | O31: =IF(N31="ON", _xlfn.IMAGE(E31, 1), "")
A32: 23-May-2025 09:29:03 | B32: Work At Height | C32: Guwahati | D32: International | E32: https://smile-ai-test.s3.ap-south-1.amazonaws.com/content/violation/wah/frame/48850_20250523T035902_wah_p.jpg | F32: 0 | G32: =IF(ISBLANK(A32), "", IF(ISBLANK(F32), 0, F32)) -> 0 | H32: =IF(ISBLANK(E32),"",HYPERLINK(E32,"Click here")) -> Click here | I32: =IFERROR(INDEX(Analysis!$D$116:$N$137, MATCH(B32, Analysis!$C$116:$C$137, 0), MATCH(C32, Analysis!$D$115:$N$115, 0)), "") -> Severe | J32: =IF(ISBLANK(A32),"",WEEKNUM(A32)) -> 21 | K32: =IF(ISBLANK(A32),"",DATE(YEAR(A32),MONTH(A32),DAY(A32))) -> 45800 | L32: =IF(A32="", "", A32 - INT(A32)) -> 0.39517361 | M32: {=IF(L32="","",_xlfn.IFS( AND(L32>=TIME(9,0,0), L32<TIME(16,0,0)),"Morning", AND(L32>=TIME(16,0,0), L32<TIME(23,59,0)),"Evening", L32>=TIME(23,59,0),"Night", L32<TIME(9,0,0),"Night" ))} -> Morning | O32: =IF(N32="ON", _xlfn.IMAGE(E32, 1), "")
... A66: 24-May-2025 09:21:14 | B66: PPE | C66: Guwahati | D66: City Side Overbridge 1 | E66: https://smile-ai-test.s3.ap-south-1.amazonaws.com/content/violation/ppe/frame/33761_20250524T035112_ppe_p.jpg | F66: 0 | G66: =IF(ISBLANK(A66), "", IF(ISBLANK(F66), 0, F66)) -> 0 | H66: =IF(ISBLANK(E66),"",HYPERLINK(E66,"Click here")) -> Click here | I66: =IFERROR(INDEX(Analysis!$D$116:$N$137, MATCH(B66, Analysis!$C$116:$C$137, 0), MATCH(C66, Analysis!$D$115:$N$115, 0)), "") -> Mild | J66: =IF(ISBLANK(A66),"",WEEKNUM(A66)) -> 21 | K66: =IF(ISBLANK(A66),"",DATE(YEAR(A66),MONTH(A66),DAY(A66))) -> 45801 | L66: =IF(A66="", "", A66 - INT(A66)) -> 0.38974537 | M66: {=IF(L66="","",_xlfn.IFS( AND(L66>=TIME(9,0,0), L66<TIME(16,0,0)),"Morning", AND(L66>=TIME(16,0,0), L66<TIME(23,59,0)),"Evening", L66>=TIME(23,59,0),"Night", L66<TIME(9,0,0),"Night" ))} -> Morning | O66: =IF(N66="ON", _xlfn.IMAGE(E66, 1), "")
G67: =IF(ISBLANK(A67), "", IF(ISBLANK(F67), 0, F67)) | H67: =IF(ISBLANK(E67),"",HYPERLINK(E67,"Click here")) | I67: =IFERROR(INDEX(Analysis!$D$116:$N$137, MATCH(B67, Analysis!$C$116:$C$137, 0), MATCH(C67, Analysis!$D$115:$N$115, 0)), "") | J67: =IF(ISBLANK(A67),"",WEEKNUM(A67)) | K67: =IF(ISBLANK(A67),"",DATE(YEAR(A67),MONTH(A67),DAY(A67))) | L67: =IF(A67="", "", A67 - INT(A67)) | M67: {=IF(L67="","",_xlfn.IFS( AND(L67>=TIME(9,0,0), L67<TIME(16,0,0)),"Morning", AND(L67>=TIME(16,0,0), L67<TIME(23,59,0)),"Evening", L67>=TIME(23,59,0),"Night", L67<TIME(9,0,0),"Night" ))} | O67: =IF(N67="ON", _xlfn.IMAGE(E67, 1), "")
G68: =IF(ISBLANK(A68), "", IF(ISBLANK(F68), 0, F68)) | H68: =IF(ISBLANK(E68),"",HYPERLINK(E68,"Click here")) | I68: =IFERROR(INDEX(Analysis!$D$116:$N$137, MATCH(B68, Analysis!$C$116:$C$137, 0), MATCH(C68, Analysis!$D$115:$N$115, 0)), "") | J68: =IF(ISBLANK(A68),"",WEEKNUM(A68)) | K68: =IF(ISBLANK(A68),"",DATE(YEAR(A68),MONTH(A68),DAY(A68))) | L68: =IF(A68="", "", A68 - INT(A68)) | M68: {=IF(L68="","",_xlfn.IFS( AND(L68>=TIME(9,0,0), L68<TIME(16,0,0)),"Morning", AND(L68>=TIME(16,0,0), L68<TIME(23,59,0)),"Evening", L68>=TIME(23,59,0),"Night", L68<TIME(9,0,0),"Night" ))} | O68: =IF(N68="ON", _xlfn.IMAGE(E68, 1), "")
G69: =IF(ISBLANK(A69), "", IF(ISBLANK(F69), 0, F69)) | H69: =IF(ISBLANK(E69),"",HYPERLINK(E69,"Click here")) | I69: =IFERROR(INDEX(Analysis!$D$116:$N$137, MATCH(B69, Analysis!$C$116:$C$137, 0), MATCH(C69, Analysis!$D$115:$N$115, 0)), "") | J69: =IF(ISBLANK(A69),"",WEEKNUM(A69)) | K69: =IF(ISBLANK(A69),"",DATE(YEAR(A69),MONTH(A69),DAY(A69))) | L69: =IF(A69="", "", A69 - INT(A69)) | M69: {=IF(L69="","",_xlfn.IFS( AND(L69>=TIME(9,0,0), L69<TIME(16,0,0)),"Morning", AND(L69>=TIME(16,0,0), L69<TIME(23,59,0)),"Evening", L69>=TIME(23,59,0),"Night", L69<TIME(9,0,0),"Night" ))} | O69: =IF(N69="ON", _xlfn.IMAGE(E69, 1), "")
G70: =IF(ISBLANK(A70), "", IF(ISBLANK(F70), 0, F70)) | H70: =IF(ISBLANK(E70),"",HYPERLINK(E70,"Click here")) | I70: =IFERROR(INDEX(Analysis!$D$116:$N$137, MATCH(B70, Analysis!$C$116:$C$137, 0), MATCH(C70, Analysis!$D$115:$N$115, 0)), "") | J70: =IF(ISBLANK(A70),"",WEEKNUM(A70)) | K70: =IF(ISBLANK(A70),"",DATE(YEAR(A70),MONTH(A70),DAY(A70))) | L70: =IF(A70="", "", A70 - INT(A70)) | M70: {=IF(L70="","",_xlfn.IFS( AND(L70>=TIME(9,0,0), L70<TIME(16,0,0)),"Morning", AND(L70>=TIME(16,0,0), L70<TIME(23,59,0)),"Evening", L70>=TIME(23,59,0),"Night", L70<TIME(9,0,0),"Night" ))} | O70: =IF(N70="ON", _xlfn.IMAGE(E70, 1), "")
G71: =IF(ISBLANK(A71), "", IF(ISBLANK(F71), 0, F71)) | H71: =IF(ISBLANK(E71),"",HYPERLINK(E71,"Click here")) | I71: =IFERROR(INDEX(Analysis!$D$116:$N$137, MATCH(B71, Analysis!$C$116:$C$137, 0), MATCH(C71, Analysis!$D$115:$N$115, 0)), "") | J71: =IF(ISBLANK(A71),"",WEEKNUM(A71)) | K71: =IF(ISBLANK(A71),"",DATE(YEAR(A71),MONTH(A71),DAY(A71))) | L71: =IF(A71="", "", A71 - INT(A71)) | M71: {=IF(L71="","",_xlfn.IFS( AND(L71>=TIME(9,0,0), L71<TIME(16,0,0)),"Morning", AND(L71>=TIME(16,0,0), L71<TIME(23,59,0)),"Evening", L71>=TIME(23,59,0),"Night", L71<TIME(9,0,0),"Night" ))} | O71: =IF(N71="ON", _xlfn.IMAGE(E71, 1), "")
G72: =IF(ISBLANK(A72), "", IF(ISBLANK(F72), 0, F72)) | H72: =IF(ISBLANK(E72),"",HYPERLINK(E72,"Click here")) | I72: =IFERROR(INDEX(Analysis!$D$116:$N$137, MATCH(B72, Analysis!$C$116:$C$137, 0), MATCH(C72, Analysis!$D$115:$N$115, 0)), "") | J72: =IF(ISBLANK(A72),"",WEEKNUM(A72)) | K72: =IF(ISBLANK(A72),"",DATE(YEAR(A72),MONTH(A72),DAY(A72))) | L72: =IF(A72="", "", A72 - INT(A72)) | M72: {=IF(L72="","",_xlfn.IFS( AND(L72>=TIME(9,0,0), L72<TIME(16,0,0)),"Morning", AND(L72>=TIME(16,0,0), L72<TIME(23,59,0)),"Evening", L72>=TIME(23,59,0),"Night", L72<TIME(9,0,0),"Night" ))} | O72: =IF(N72="ON", _xlfn.IMAGE(E72, 1), "")
G73: =IF(ISBLANK(A73), "", IF(ISBLANK(F73), 0, F73)) | H73: =IF(ISBLANK(E73),"",HYPERLINK(E73,"Click here")) | I73: =IFERROR(INDEX(Analysis!$D$116:$N$137, MATCH(B73, Analysis!$C$116:$C$137, 0), MATCH(C73, Analysis!$D$115:$N$115, 0)), "") | J73: =IF(ISBLANK(A73),"",WEEKNUM(A73)) | K73: =IF(ISBLANK(A73),"",DATE(YEAR(A73),MONTH(A73),DAY(A73))) | L73: =IF(A73="", "", A73 - INT(A73)) | M73: {=IF(L73="","",_xlfn.IFS( AND(L73>=TIME(9,0,0), L73<TIME(16,0,0)),"Morning", AND(L73>=TIME(16,0,0), L73<TIME(23,59,0)),"Evening", L73>=TIME(23,59,0),"Night", L73<TIME(9,0,0),"Night" ))} | O73: =IF(N73="ON", _xlfn.IMAGE(E73, 1), "")
...

Sheet Analysis
H1: number of cameras | I1: =COUNTA(C61:C81) -> 9
C2: Violation type | D2: Count of violations | E2: Top Two | H2: =IF('Raw Data'!K2="", "", TEXT(MIN('Raw Data'!K2:K5000), "DD/MM/YYYY") & " to " & TEXT(MAX('Raw Data'!K2:K5000), "DD/MM/YYYY")) -> 22/05/2025 to 24/05/2025 | AO2: {=OFFSET($AF$2, 0, 0, COUNTA($AF$2:$AF$7), 1)} -> #REF!
C3: {=_xlfn.LET( _xlpm.rawDataRange, 'Raw Data'!B2:B5000, _xlpm.nonEmptyCount, COUNTIF(_xlpm.rawDataRange, "<>"), IF( _xlpm.nonEmptyCount = 0, "", _xlfn.LET( _xlpm.rawData, _xlfn._xlws.FILTER(_xlpm.rawDataRange, _xlpm.rawDataRange<>""), _xlpm.uniqueVals, _xlfn.UNIQUE(_xlpm.rawData), _xlpm.counts, COUNTIF(_xlpm.rawDataRange, _xlpm.uniqueVals), _xlpm.sortedData, _xlfn.SORTBY(_xlfn.HSTACK(_xlpm.uniqueVals, _xlpm.counts), _xlpm.counts, -1), _xlpm.sortedData ) ) )} -> PPE | D3: 33 | E3: =IF(COUNT($D$3:$D$25)=0, "", IF(OR(D3=LARGE($D$3:$D$25, 1), D3=LARGE($D$3:$D$25, 2)), D3, "")) -> 33
C4: Welding / Gas cutting | D4: 13 | E4: =IF(COUNT($D$3:$D$25)=0, "", IF(OR(D4=LARGE($D$3:$D$25, 1), D4=LARGE($D$3:$D$25, 2)), D4, "")) -> 13 | H4: {=IF(SUMPRODUCT(--(LEN(TRIM(C3:C13))>0))=0, "No violation is present", IF(SUMPRODUCT(--(LEN(TRIM(C4:C13))>0))=0, "Behavior is the major factor in nearly 90% of total violations is " & C3, "Behavior is the major factor in nearly 90% of total violations: " & _xlfn.TEXTJOIN(", ", TRUE, _xlfn._xlws.FILTER(C3:C13, ISNUMBER(MATCH(D3:D13, E3:E13, 0)))) ) )} -> Behavior is the major factor in nearly 90% of total violations: PPE, Welding / Gas cutting
C5: Work At Height | D5: 9
C6: Vehicle Reverse Flagman | D6: 6 | E6: =IF(COUNT($D$3:$D$25)=0, "", IF(OR(D6=LARGE($D$3:$D$25, 1), D6=LARGE($D$3:$D$25, 2)), D6, "")) | H6: Critical violations like Fall Protection & Hit by Object/Vehicle needs training
C7: Unconscious/Resting | D7: 2 | E7: =IF(COUNT($D$3:$D$25)=0, "", IF(OR(D7=LARGE($D$3:$D$25, 1), D7=LARGE($D$3:$D$25, 2)), D7, ""))
C8: Unauthorized Access | D8: 2 | E8: =IF(COUNT($D$3:$D$25)=0, "", IF(OR(D8=LARGE($D$3:$D$25, 1), D8=LARGE($D$3:$D$25, 2)), D8, ""))
E9: =IF(COUNT($D$3:$D$25)=0, "", IF(OR(D9=LARGE($D$3:$D$25, 1), D9=LARGE($D$3:$D$25, 2)), D9, ""))
E10: =IF(COUNT($D$3:$D$25)=0, "", IF(OR(D10=LARGE($D$3:$D$25, 1), D10=LARGE($D$3:$D$25, 2)), D10, ""))
E11: =IF(COUNT($D$3:$D$25)=0, "", IF(OR(D11=LARGE($D$3:$D$25, 1), D11=LARGE($D$3:$D$25, 2)), D11, ""))
E12: =IF(COUNT($D$3:$D$25)=0, "", IF(OR(D12=LARGE($D$3:$D$25, 1), D12=LARGE($D$3:$D$25, 2)), D12, ""))
E13: =IF(COUNT($D$3:$D$25)=0, "", IF(OR(D13=LARGE($D$3:$D$25, 1), D13=LARGE($D$3:$D$25, 2)), D13, ""))
E14: =IF(COUNT($D$3:$D$25)=0, "", IF(OR(D14=LARGE($D$3:$D$25, 1), D14=LARGE($D$3:$D$25, 2)), D14, "")) | Q14: =IF(O14<>"", COUNTIFS('Raw Data'!D13:D5011, O14, 'Raw Data'!G13:G5011, 1), "") | R14: =IF(O14<>"", COUNTIFS('Raw Data'!D13:D5011, O14, 'Raw Data'!G13:G5011, 0), "")
E15: =IF(COUNT($D$3:$D$25)=0, "", IF(OR(D15=LARGE($D$3:$D$25, 1), D15=LARGE($D$3:$D$25, 2)), D15, ""))
E16: =IF(COUNT($D$3:$D$25)=0, "", IF(OR(D16=LARGE($D$3:$D$25, 1), D16=LARGE($D$3:$D$25, 2)), D16, ""))
E17: =IF(COUNT($D$3:$D$25)=0, "", IF(OR(D17=LARGE($D$3:$D$25, 1), D17=LARGE($D$3:$D$25, 2)), D17, ""))
E18: =IF(COUNT($D$3:$D$25)=0, "", IF(OR(D18=LARGE($D$3:$D$25, 1), D18=LARGE($D$3:$D$25, 2)), D18, ""))
E19: =IF(COUNT($D$3:$D$25)=0, "", IF(OR(D19=LARGE($D$3:$D$25, 1), D19=LARGE($D$3:$D$25, 2)), D19, ""))
E20: =IF(COUNT($D$3:$D$25)=0, "", IF(OR(D20=LARGE($D$3:$D$25, 1), D20=LARGE($D$3:$D$25, 2)), D20, ""))
E21: =IF(COUNT($D$3:$D$25)=0, "", IF(OR(D21=LARGE($D$3:$D$25, 1), D21=LARGE($D$3:$D$25, 2)), D21, ""))
E22: =IF(COUNT($D$3:$D$25)=0, "", IF(OR(D22=LARGE($D$3:$D$25, 1), D22=LARGE($D$3:$D$25, 2)), D22, ""))
E23: =IF(COUNT($D$3:$D$25)=0, "", IF(OR(D23=LARGE($D$3:$D$25, 1), D23=LARGE($D$3:$D$25, 2)), D23, ""))
E24: =IF(COUNT($D$3:$D$25)=0, "", IF(OR(D24=LARGE($D$3:$D$25, 1), D24=LARGE($D$3:$D$25, 2)), D24, ""))
E25: =IF(COUNT($D$3:$D$25)=0, "", IF(OR(D25=LARGE($D$3:$D$25, 1), D25=LARGE($D$3:$D$25, 2)), D25, ""))
E26: =IF(COUNT($D$3:$D$25)=0, "", IF(OR(D26=LARGE($D$3:$D$25, 1), D26=LARGE($D$3:$D$25, 2)), D26, ""))
... E31: =IF(COUNT($D$3:$D$25)=0, "", IF(OR(D31=LARGE($D$3:$D$25, 1), D31=LARGE($D$3:$D$25, 2)), D31, ""))
C32: TOTAL | D32: =SUM(D3:D31) -> 65
Q37: =IF(O37<>"", COUNTIFS('Raw Data'!D14:D5012, O37, 'Raw Data'!G14:G5012, 1), "") | R37: =IF(O37<>"", COUNTIFS('Raw Data'!D14:D5012, O37, 'Raw Data'!G14:G5012, 0), "")
Q38: =IF(O38<>"", COUNTIFS('Raw Data'!D15:D5013, O38, 'Raw Data'!G15:G5013, 1), "") | R38: =IF(O38<>"", COUNTIFS('Raw Data'!D15:D5013, O38, 'Raw Data'!G15:G5013, 0), "")
C39: Week_num | D39: Week | E39: Morning | F39: Evening | G39: night
C40: {=_xlfn.LET( _xlpm.dataRange, 'Raw Data'!J2:J5000, _xlpm.nonBlankCount, SUMPRODUCT(--(TRIM(_xlpm.dataRange)<>"")), IF(_xlpm.nonBlankCount=0, "", _xlfn.LET( _xlpm.w, _xlfn._xlws.FILTER(_xlpm.dataRange, (_xlpm.dataRange<>"")*(_xlpm.dataRange<>0)), _xlpm.uW, _xlfn._xlws.SORT(_xlfn.UNIQUE(_xlpm.w)), _xlpm.cW, COUNTA(_xlpm.uW), _xlpm.wL, "Week-" & TEXT(_xlfn.SEQUENCE(_xlpm.cW,,1,1), "00"), _xlpm.mC, COUNTIFS(_xlpm.dataRange, _xlpm.uW, 'Raw Data'!M2:M5000, "Morning"), _xlpm.eC, COUNTIFS(_xlpm.dataRange, _xlpm.uW, 'Raw Data'!M2:M5000, "Evening"), _xlpm.nC, COUNTIFS(_xlpm.dataRange, _xlpm.uW, 'Raw Data'!M2:M5000, "Night"), IF(_xlpm.cW=0, {"No Data","Week-00",0,0,0}, CHOOSE({1,2,3,4,5}, _xlpm.uW, _xlpm.wL, _xlpm.mC, _xlpm.eC, _xlpm.nC) ) ) ) )} -> 21 | D40: Week-01 | E40: 48 | F40: 17 | G40: 0
C46: TOTAL | E46: =SUM(E40:E45) -> 48 | F46: =SUM(F40:F45) -> 17 | G46: =SUM(G40:G45) -> 0
C49: Week_num | D49: Week | E49: Mild | F49: Critical | G49: No of days | H49: Daily Avg
C50: {=IF(COUNTA('Raw Data'!J2:J5000)=0, "", IFERROR(_xlfn.LET( _xlpm.w, _xlfn._xlws.SORT(_xlfn.UNIQUE(_xlfn._xlws.FILTER('Raw Data'!J2:J5000, ('Raw Data'!J2:J5000<>"") * ISNUMBER('Raw Data'!J2:J5000)))), _xlpm.wl, "Week-" & TEXT(_xlfn.SEQUENCE(ROWS(_xlpm.w), 1, 1), "00"), _xlpm.mildCount, _xlfn.BYROW(_xlpm.w, _xlfn.LAMBDA(_xlpm.c, SUMPRODUCT(('Raw Data'!J2:J5000 = _xlpm.c) * ('Raw Data'!I2:I5000 = "Mild")))), _xlpm.severeCount, _xlfn.BYROW(_xlpm.w, _xlfn.LAMBDA(_xlpm.c, SUMPRODUCT(('Raw Data'!J2:J5000 = _xlpm.c) * ('Raw Data'!I2:I5000 = "Severe")))), _xlpm.u, _xlfn.BYROW(_xlpm.w, _xlfn.LAMBDA(_xlpm.x, _xlfn.LET(_xlpm.v, _xlfn._xlws.FILTER('Raw Data'!K2:K5000, 'Raw Data'!J2:J5000 = _xlpm.x), _xlpm.c, _xlfn._xlws.FILTER(_xlpm.v, LEN(_xlpm.v) > 0), _xlpm.r, COUNTA(_xlfn.UNIQUE(_xlpm.c)), IF(_xlpm.r > 7, 7, _xlpm.r)))), _xlpm.a, _xlfn.BYROW(_xlfn.HSTACK(_xlpm.mildCount, _xlpm.severeCount, _xlpm.u), _xlfn.LAMBDA(_xlpm.r, _xlfn.LET(_xlpm.g, INDEX(_xlpm.r, 1), _xlpm.o, INDEX(_xlpm.r, 2), _xlpm.u, INDEX(_xlpm.r, 3), IF(_xlpm.u = 0, 0, ROUND((_xlpm.g + _xlpm.o) / _xlpm.u, 0))))), _xlfn.HSTACK(_xlpm.w, _xlpm.wl, _xlpm.mildCount, _xlpm.severeCount, _xlpm.u, _xlpm.a) ), ""))} -> 21 | D50: Week-01 | E50: 46 | F50: 19 | G50: 3 | H50: 22
C56: TOTAL | E56: =SUM(E50:E55) -> 46 | F56: =SUM(F50:F55) -> 19 | G56: =SUM(G50:G55) -> 3 | H56: =SUM(H50:H55) -> 22
C60: camera_name | D60: COUNTS | E60: Resolved | F60: Unresolved | G60: Rejected
C61: {=IF(COUNTA('Raw Data'!D2:D5000)=0, "", CHOOSE( {1,2,3,4,5}, _xlfn._xlws.SORT(_xlfn.UNIQUE(_xlfn._xlws.FILTER('Raw Data'!D2:D5000, 'Raw Data'!D2:D5000<>""))), COUNTIF('Raw Data'!D2:D5000, _xlfn._xlws.SORT(_xlfn.UNIQUE(_xlfn._xlws.FILTER('Raw Data'!D2:D5000, 'Raw Data'!D2:D5000<>"")))), COUNTIFS('Raw Data'!D2:D5000, _xlfn._xlws.SORT(_xlfn.UNIQUE(_xlfn._xlws.FILTER('Raw Data'!D2:D5000, 'Raw Data'!D2:D5000<>""))), 'Raw Data'!G2:G5000, 1), COUNTIFS('Raw Data'!D2:D5000, _xlfn._xlws.SORT(_xlfn.UNIQUE(_xlfn._xlws.FILTER('Raw Data'!D2:D5000, 'Raw Data'!D2:D5000<>""))), 'Raw Data'!G2:G5000, 0), COUNTIFS('Raw Data'!D2:D5000, _xlfn._xlws.SORT(_xlfn.UNIQUE(_xlfn._xlws.FILTER('Raw Data'!D2:D5000, 'Raw Data'!D2:D5000<>""))), 'Raw Data'!G2:G5000, 2) ) )} -> AirSide | D61: 2 | E61: 0 | F61: 2 | G61: 0
C62: Arrival Zone 4 | D62: 5 | E62: 0 | F62: 5 | G62: 0
C63: City Side HM | D63: 9 | E63: 0 | F63: 9 | G63: 0
...

Sheet final report sheet
B2: Safety Inspection at a glance | J2: Monthly Captured Violations: | M2: =Analysis!D32 -> 65
B3: Unnoticed today, near-miss tomorrow, may lead to incident any day | J3: FROM | K3: =Analysis!H2 -> 22/05/2025 to 24/05/2025
L5: Violation type | M5: Count of violations
L6: {=_xlfn.LET( _xlpm.rawDataRange, 'Raw Data'!B2:B5000, _xlpm.nonEmptyCount, COUNTIF(_xlpm.rawDataRange, "<>"), IF( _xlpm.nonEmptyCount = 0, "", _xlfn.LET( _xlpm.rawData, _xlfn._xlws.FILTER(_xlpm.rawDataRange, _xlpm.rawDataRange<>""), _xlpm.uniqueVals, _xlfn.UNIQUE(_xlpm.rawData), _xlpm.counts, COUNTIF(_xlpm.rawDataRange, _xlpm.uniqueVals), _xlpm.sortedData, _xlfn.SORTBY(_xlfn.HSTACK(_xlpm.uniqueVals, _xlpm.counts), _xlpm.counts, -1), _xlpm.sortedData ) ) )} -> PPE | M6: 33
L7: Welding / Gas cutting | M7: 13
L8: Work At Height | M8: 9
L9: Vehicle Reverse Flagman | M9: 6
L10: Unconscious/Resting | M10: 2
L11: Unauthorized Access | M11: 2
B25: =Analysis!H6 -> Critical violations like Fall Protection & Hit by Object/Vehicle needs training
B27: =Analysis!H4 -> Behavior is the major factor in nearly 90% of total violations: PPE, Welding / Gas cutting | L27: TOTAL | M27: =SUM(M6:M26) -> 65
M29: =IF('Raw Data'!C2="", "No locations", 'Raw Data'!C2) -> Guwahati
B31: Location-wise overview | K31: Total number of cameras | M31: =Analysis!I1 -> 9
B32: Insights for customized action-plan
D51: Insights on major areas
A53: =IF(B53="", "", 1) -> 1 | B53: =Analysis!U87 -> Work At Height has the highest events at International, Front Office
A55: =IF(B55="", "", 2) -> 2 | B55: =Analysis!U88 -> Vehicle Reverse Flagman has the highest events at Departure, Zone 5, International
A57: =IF(B57="", "", 3) -> 3 | B57: =Analysis!U89 -> Unauthorized Access has the highest events at Front Office, International
A59: =IF(B59="", "", 4) -> 4 | B59: =Analysis!U90 -> Unconscious/Resting has the highest events at City Side Overbridge 1, City Side Overbridge 1
M60: =IF('Raw Data'!C2="", "No locations", 'Raw Data'!C2) -> Guwahati
B62: Moving towards improvements | J62: Corrective actions & closures of unsafe condition
B63: ="Weekly trends for the " & TEXT('Raw Data'!A2, "mmmm") -> Weekly trends for the May
M91: =IF('Raw Data'!C2="", "No locations", 'Raw Data'!C2) -> Guwahati
B93: Weekly Progress of Shift-Wise | J93: Corrective actions & closures of unsafe condition
B94: ="Weekly trends for the " & TEXT('Raw Data'!A2, "mmmm") -> Weekly trends for the May
K98: Morning: | L98: 8:00 AM – 3:59 PM
K99: Evening: | L99: 4:00 PM – 11:59 PM
K100: Night: | L100: 12:00 AM – 7:59 AM
M122: =IF('Raw Data'!C2="", "No locations", 'Raw Data'!C2) -> Guwahati
B124: Actions taken on the violation
B125: Reolved, Unresolved or Rejected
M154: =IF('Raw Data'!C2="", "No locations", 'Raw Data'!C2) -> Guwahati
